<?xml version="1.0" ?>
<!-- =================================================================================== -->
<!-- |    This document was autogenerated by xacro from inmoov_wohand.urdf.xacro       | -->
<!-- |    EDITING THIS FILE BY HAND IS NOT RECOMMENDED                                 | -->
<!-- =================================================================================== -->
<robot name="inmoov" xmlns:xacro="http://ros.org/wiki/xacro">
  <!--xacro:property name="pi" value="3.1415926539"/-->
  <!-- meshlab steps taken from http://gazebosim.org/tutorials?tut=inertia -->
  <!-- assume material density is 1.0g per 1.0cm^2 -->
  <!-- ABS is 1.04g per 1.0cm^3 -->
  <!-- PLA is 1.25g per 1.0cm^3 -->
  <!-- based on https://github.com/ros-simulation/gazebo_ros_demos/blob/kinetic-devel/rrbot_description/urdf/rrbot.gazebo -->
  <!-- ros_control plugin -->
  <gazebo>
    <plugin filename="libgazebo_ros_control.so" name="gazebo_ros_control">
      <robotNamespace>/inmoov</robotNamespace>
      <robotSimType>gazebo_ros_control/DefaultRobotHWSim</robotSimType>
    </plugin>
  </gazebo>
  <!-- colors for torso links -->
  <gazebo reference="mid_stomach_link">
    <material>Gazebo/Grey</material>
  </gazebo>
  <gazebo reference="disk_link">
    <material>Gazebo/White</material>
  </gazebo>
  <gazebo reference="top_stomach_link">
    <material>Gazebo/Grey</material>
  </gazebo>
  <gazebo reference="torso_link">
    <material>Gazebo/Grey</material>
  </gazebo>
  <gazebo reference="kinect2_link">
    <material>Gazebo/DarkGrey</material>
  </gazebo>
  <gazebo reference="kinect2_ir_optical_frame_link">
    <material>Gazebo/DarkGrey</material>
  </gazebo>
  <gazebo reference="kinect2_rgb_optical_frame_link">
    <material>Gazebo/DarkGrey</material>
  </gazebo>
  <gazebo reference="chestplate_link">
    <material>Gazebo/White</material>
  </gazebo>
  <!-- colors for head links -->
  <gazebo reference="head_base_link">
    <material>Gazebo/Grey</material>
  </gazebo>
  <gazebo reference="head_link">
    <material>Gazebo/Grey</material>
  </gazebo>
  <gazebo reference="jaw_link">
    <material>Gazebo/White</material>
  </gazebo>
  <gazebo reference="skull_link">
    <material>Gazebo/White</material>
  </gazebo>
  <gazebo reference="left_ear_link">
    <material>Gazebo/Grey</material>
  </gazebo>
  <gazebo reference="right_ear_link">
    <material>Gazebo/Grey</material>
  </gazebo>
  <!-- colors for head links -->
  <gazebo reference="face_link">
    <material>Gazebo/White</material>
  </gazebo>
  <!-- colors for eye links -->
  <gazebo reference="l_eyesupport_link">
    <material>Gazebo/Grey</material>
  </gazebo>
  <gazebo reference="r_eyesupport_link">
    <material>Gazebo/Grey</material>
  </gazebo>
  <gazebo reference="l_camera_link">
    <material>Gazebo/DarkGrey</material>
  </gazebo>
  <gazebo reference="r_camera_link">
    <material>Gazebo/DarkGrey</material>
  </gazebo>
  <gazebo reference="l_eye_link">
    <material>Gazebo/White</material>
  </gazebo>
  <gazebo reference="r_eye_link">
    <material>Gazebo/White</material>
  </gazebo>
  <gazebo reference="l_iris_link">
    <material>Gazebo/SkyBlue</material>
  </gazebo>
  <gazebo reference="r_iris_link">
    <material>Gazebo/SkyBlue</material>
  </gazebo>
  <!-- colors for arm links -->
  <gazebo reference="l_shoulder_base_link">
    <material>Gazebo/Grey</material>
  </gazebo>
  <gazebo reference="r_shoulder_base_link">
    <material>Gazebo/Grey</material>
  </gazebo>
  <gazebo reference="l_shoulder_link">
    <material>Gazebo/Grey</material>
  </gazebo>
  <gazebo reference="r_shoulder_link">
    <material>Gazebo/Grey</material>
  </gazebo>
  <gazebo reference="l_bicep_link">
    <material>Gazebo/Grey</material>
  </gazebo>
  <gazebo reference="r_bicep_link">
    <material>Gazebo/Grey</material>
  </gazebo>
  <gazebo reference="l_bicepcover_link">
    <material>Gazebo/White</material>
  </gazebo>
  <gazebo reference="r_bicepcover_link">
    <material>Gazebo/White</material>
  </gazebo>
  <gazebo reference="l_forearm_link">
    <material>Gazebo/White</material>
  </gazebo>
  <gazebo reference="r_corearm_link">
    <material>Gazebo/White</material>
  </gazebo>
  <!-- colors for hand links -->
  <gazebo reference="l_hand_link">
    <material>Gazebo/Grey</material>
  </gazebo>
  <gazebo reference="r_hand_link">
    <material>Gazebo/Grey</material>
  </gazebo>
  <gazebo reference="l_thumb1_link">
    <material>Gazebo/Grey</material>
  </gazebo>
  <gazebo reference="r_thumb1_link">
    <material>Gazebo/Grey</material>
  </gazebo>
  <gazebo reference="l_thumb2_link">
    <material>Gazebo/Grey</material>
  </gazebo>
  <gazebo reference="r_thumb2_link">
    <material>Gazebo/Grey</material>
  </gazebo>
  <gazebo reference="l_thumb3_link">
    <material>Gazebo/Grey</material>
  </gazebo>
  <gazebo reference="r_thumb3_link">
    <material>Gazebo/Grey</material>
  </gazebo>
  <gazebo reference="l_index1_link">
    <material>Gazebo/Grey</material>
  </gazebo>
  <gazebo reference="r_index1_link">
    <material>Gazebo/Grey</material>
  </gazebo>
  <gazebo reference="l_index2_link">
    <material>Gazebo/Grey</material>
  </gazebo>
  <gazebo reference="r_index2_link">
    <material>Gazebo/Grey</material>
  </gazebo>
  <gazebo reference="l_index3_link">
    <material>Gazebo/Grey</material>
  </gazebo>
  <gazebo reference="r_index3_link">
    <material>Gazebo/Grey</material>
  </gazebo>
  <gazebo reference="l_middle1_link">
    <material>Gazebo/Grey</material>
  </gazebo>
  <gazebo reference="r_middle1_link">
    <material>Gazebo/Grey</material>
  </gazebo>
  <gazebo reference="l_middle2_link">
    <material>Gazebo/Grey</material>
  </gazebo>
  <gazebo reference="r_middle2_link">
    <material>Gazebo/Grey</material>
  </gazebo>
  <gazebo reference="l_middle3_link">
    <material>Gazebo/Grey</material>
  </gazebo>
  <gazebo reference="r_middle3_link">
    <material>Gazebo/Grey</material>
  </gazebo>
  <gazebo reference="l_ring1_link">
    <material>Gazebo/Grey</material>
  </gazebo>
  <gazebo reference="r_ring1_link">
    <material>Gazebo/Grey</material>
  </gazebo>
  <gazebo reference="l_ring2_link">
    <material>Gazebo/Grey</material>
  </gazebo>
  <gazebo reference="r_ring2_link">
    <material>Gazebo/Grey</material>
  </gazebo>
  <gazebo reference="l_ring3_link">
    <material>Gazebo/Grey</material>
  </gazebo>
  <gazebo reference="r_ring3_link">
    <material>Gazebo/Grey</material>
  </gazebo>
  <gazebo reference="l_ring4_link">
    <material>Gazebo/Grey</material>
  </gazebo>
  <gazebo reference="r_ring4_link">
    <material>Gazebo/Grey</material>
  </gazebo>
  <gazebo reference="l_pinky1_link">
    <material>Gazebo/Grey</material>
  </gazebo>
  <gazebo reference="r_pinky1_link">
    <material>Gazebo/Grey</material>
  </gazebo>
  <gazebo reference="l_pinky2_link">
    <material>Gazebo/Grey</material>
  </gazebo>
  <gazebo reference="r_pinky2_link">
    <material>Gazebo/Grey</material>
  </gazebo>
  <gazebo reference="l_pinky3_link">
    <material>Gazebo/Grey</material>
  </gazebo>
  <gazebo reference="r_pinky3_link">
    <material>Gazebo/Grey</material>
  </gazebo>
  <gazebo reference="l_pinky4_link">
    <material>Gazebo/Grey</material>
  </gazebo>
  <gazebo reference="r_pinky4_link">
    <material>Gazebo/Grey</material>
  </gazebo>
  <gazebo reference="l_handcover_link">
    <material>Gazebo/White</material>
  </gazebo>
  <gazebo reference="r_handcover_link">
    <material>Gazebo/White</material>
  </gazebo>
  <gazebo reference="l_cover_handring_link">
    <material>Gazebo/White</material>
  </gazebo>
  <gazebo reference="r_cover_handring_link">
    <material>Gazebo/White</material>
  </gazebo>
  <gazebo reference="l_cover_handpinky_link">
    <material>Gazebo/White</material>
  </gazebo>
  <gazebo reference="r_cover_handpinky_link">
    <material>Gazebo/White</material>
  </gazebo>
  <gazebo reference="l_cover_thumb_link">
    <material>Gazebo/White</material>
  </gazebo>
  <gazebo reference="r_cover_thumb_link">
    <material>Gazebo/White</material>
  </gazebo>
  <gazebo reference="l_cover_index_link">
    <material>Gazebo/White</material>
  </gazebo>
  <gazebo reference="r_cover_index_link">
    <material>Gazebo/White</material>
  </gazebo>
  <gazebo reference="l_cover_middle_link">
    <material>Gazebo/White</material>
  </gazebo>
  <gazebo reference="r_cover_middle_link">
    <material>Gazebo/White</material>
  </gazebo>
  <gazebo reference="l_cover_ring_link">
    <material>Gazebo/White</material>
  </gazebo>
  <gazebo reference="r_cover_ring_link">
    <material>Gazebo/White</material>
  </gazebo>
  <gazebo reference="l_cover_pinky_link">
    <material>Gazebo/White</material>
  </gazebo>
  <gazebo reference="r_cover_pinky_link">
    <material>Gazebo/White</material>
  </gazebo>
  <link name="world"/>
  <joint name="fixed" type="fixed">
    <parent link="world"/>
    <child link="base_link"/>
  </joint>
  <link name="base_link">
    <visual>
      <geometry>
        <cylinder length="0.11" radius="0.26"/>
      </geometry>
      <origin rpy="0 0 0" xyz="0 0 0.055"/>
      <material name="cbase">
        <color rgba="0.1 0.1 0.1 1"/>
      </material>
    </visual>
  </link>
  <joint name="base_to_pedestal_link" type="fixed">
    <parent link="base_link"/>
    <child link="pedestal_link"/>
    <origin rpy="0 0 0" xyz="0 0 0"/>
  </joint>
  <link name="pedestal_link">
    <visual>
      <geometry>
        <cylinder length="0.94" radius="0.0254"/>
      </geometry>
      <origin rpy="0 0 0" xyz="0 0 0.58"/>
      <material name="cbase">
        <color rgba="0.1 0.1 0.1 1"/>
      </material>
    </visual>
  </link>
  <link name="head_tilt_link">
    <visual>
      <geometry>
        <mesh filename="package://inmoov_meshes/meshes/virtual.stl" scale="0.001 0.001 0.001"/>
      </geometry>
      <origin rpy="0 0 3.1415" xyz="0 0 0"/>
      <material name="cframe">
        <color rgba="0.40 0.40 0.40 1"/>
      </material>
    </visual>
    <inertial>
      <mass value="0.001"/>
      <inertia ixx="1.66667e-10" ixy="0.0" ixz="0.0" iyy="1.66667e-10" iyz="0.0" izz="1.66667e-10"/>
    </inertial>
  </link>
  <joint name="pedestal_to_mid_stomach_joint" type="fixed">
    <parent link="pedestal_link"/>
    <child link="mid_stomach_link"/>
    <origin rpy="0 0 0" xyz="0 0 0"/>
  </joint>
  <link name="mid_stomach_link">
    <visual>
      <geometry>
        <mesh filename="package://inmoov_meshes/meshes/mid_stomach.stl" scale="0.001 0.001 0.001"/>
      </geometry>
      <origin rpy="0 0 0" xyz="0 0 1.152"/>
      <material name="cframe">
        <color rgba="0.40 0.40 0.40 1"/>
      </material>
    </visual>
    <inertial>
      <mass value="1710.217625"/>
      <inertia ixx="10.129861632" ixy="0.001797694125" ixz="0.205381024" iyy="4.40146688" iyz="-0.000721074" izz="10.623296512"/>
    </inertial>
  </link>
  <link name="disk_link">
    <visual>
      <geometry>
        <mesh filename="package://inmoov_meshes/meshes/disk.stl" scale="0.001 0.001 0.001"/>
      </geometry>
      <origin rpy="0 0 0" xyz="0 0 0"/>
      <material name="ccover">
        <color rgba="0.75 0.75 0.75 1.0"/>
      </material>
    </visual>
    <inertial>
      <mass value="178.96734375"/>
      <inertia ixx="0.518276192" ixy="-3.94440735e-07" ixz="0.012957092" iyy="0.264527408" iyz="1.5683143555e-05" izz="0.268095952"/>
    </inertial>
  </link>
  <link name="top_stomach_link">
    <visual>
      <geometry>
        <mesh filename="package://inmoov_meshes/meshes/top_stomach.stl" scale="0.001 0.001 0.001"/>
      </geometry>
      <origin rpy="0 0 0" xyz="0 0 0"/>
      <material name="cframe">
        <color rgba="0.40 0.40 0.40 1"/>
      </material>
    </visual>
    <inertial>
      <mass value="1144.88975"/>
      <inertia ixx="5.824147968" ixy="0.00452986" ixz="-0.222818176" iyy="4.174386432" iyz="0.00410783" izz="5.962789376"/>
    </inertial>
  </link>
  <link name="torso_link">
    <visual>
      <geometry>
        <mesh filename="package://inmoov_meshes/meshes/torso.stl" scale="0.001 0.001 0.001"/>
      </geometry>
      <origin rpy="0 0 0" xyz="0 0 0"/>
      <material name="cframe">
        <color rgba="0.40 0.40 0.40 1"/>
      </material>
    </visual>
    <inertial>
      <mass value="1923.29375"/>
      <inertia ixx="35.26709248" ixy="0.0069580865" ixz="0.730539008" iyy="25.724428288" iyz="-0.01522677" izz="13.365055488"/>
    </inertial>
  </link>
  <link name="kinect2_link">
    <visual>
      <geometry>
        <mesh filename="package://inmoov_meshes/meshes/kinectone.stl" scale="0.001 0.001 0.001"/>
      </geometry>
      <origin rpy="1.57 0 0" xyz="0 0 0"/>
      <material name="ckinect">
        <color rgba="0.1 0.1 0.1 1"/>
      </material>
    </visual>
    <inertial>
      <mass value="790.8319375"/>
      <inertia ixx="0.539265728" ixy="-0.008770675" ixz="-0.0023443175" iyy="3.865038592" iyz="0.025915652" izz="3.969101824"/>
    </inertial>
  </link>
  <link name="kinect2_ir_optical_frame">
    <visual>
      <geometry>
        <mesh filename="package://inmoov_meshes/meshes/kinectone.stl" scale="0.001 0.001 0.001"/>
      </geometry>
      <origin rpy="1.57 0 0" xyz="0 0 0"/>
      <material name="ckinect">
        <color rgba="0.1 0.1 0.1 1"/>
      </material>
    </visual>
    <inertial>
      <mass value="790.8319375"/>
      <inertia ixx="0.539265728" ixy="-0.008770675" ixz="-0.0023443175" iyy="3.865038592" iyz="0.025915652" izz="3.969101824"/>
    </inertial>
  </link>
  <link name="kinect2_rgb_optical_frame">
    <visual>
      <geometry>
        <mesh filename="package://inmoov_meshes/meshes/kinectone.stl" scale="0.001 0.001 0.001"/>
      </geometry>
      <origin rpy="1.57 0 0" xyz="0 0 0"/>
      <material name="ckinect">
        <color rgba="0.1 0.1 0.1 1"/>
      </material>
    </visual>
    <inertial>
      <mass value="790.8319375"/>
      <inertia ixx="0.539265728" ixy="-0.008770675" ixz="-0.0023443175" iyy="3.865038592" iyz="0.025915652" izz="3.969101824"/>
    </inertial>
  </link>
  <link name="chestplate_link">
    <visual>
      <geometry>
        <mesh filename="package://inmoov_meshes/meshes/chest.stl" scale="0.001 0.001 0.001"/>
      </geometry>
      <origin rpy="0 0 0" xyz="0 0 0"/>
      <material name="ccover">
        <color rgba="0.75 0.75 0.75 1.0"/>
      </material>
    </visual>
    <inertial>
      <mass value="755.6806875"/>
      <inertia ixx="7.996578816" ixy="-0.0004753828125" ixz="-0.051810308" iyy="3.795706624" iyz="0.011253427" izz="4.511691776"/>
    </inertial>
  </link>
  <joint name="waist_pan_joint" type="revolute">
    <axis xyz="0 0 1"/>
    <limit effort="1000.0" lower="-3.14159265359" upper="3.14159265359" velocity="1745.32925199"/>
    <origin rpy="0 0 0" xyz="0 0 1.152"/>
    <parent link="mid_stomach_link"/>
    <child link="top_stomach_link"/>
  </joint>
  <joint name="disk_joint" type="fixed">
    <origin rpy="0 0 0" xyz="0.046 0 0.09"/>
    <parent link="top_stomach_link"/>
    <child link="disk_link"/>
  </joint>
  <joint name="waist_roll_joint" type="revolute">
    <axis xyz="1 0 0"/>
    <limit effort="1000.0" lower="-3.14159265359" upper="3.14159265359" velocity="1745.32925199"/>
    <origin rpy="0 0 0" xyz="0 0 0.11"/>
    <parent link="top_stomach_link"/>
    <child link="torso_link"/>
  </joint>
  <joint name="chestplate_joint" type="fixed">
    <origin rpy="0 0 0" xyz="0.042 0 0.025"/>
    <parent link="torso_link"/>
    <child link="chestplate_link"/>
  </joint>
  <joint name="kinect2_joint" type="fixed">
    <origin rpy="-1.57 0 -1.57" xyz="0 0 0.066"/>
    <parent link="torso_link"/>
    <child link="kinect2_link"/>
  </joint>
  <joint name="kinect2_ir_optical_frame_joint" type="fixed">
    <origin rpy="-1.57 0 -1.57" xyz="0 0 0.066"/>
    <parent link="torso_link"/>
    <child link="kinect2_ir_optical_frame"/>
  </joint>
  <joint name="kinect2_rgb_optical_joint" type="fixed">
    <origin rpy="-1.57 0 -1.57" xyz="0 0 0.066"/>
    <parent link="torso_link"/>
    <child link="kinect2_rgb_optical_frame"/>
  </joint>
  <joint name="head_roll_joint" type="revolute">
    <axis xyz="1 0 0"/>
    <limit effort="1000.0" lower="-3.14159265359" upper="3.14159265359" velocity="1745.32925199"/>
    <origin rpy="0 0 3.1415" xyz="-0.0315  -0.001 0.4551"/>
    <parent link="torso_link"/>
    <child link="head_tilt_link"/>
  </joint>
  <joint name="head_tilt_joint" type="revolute">
    <axis xyz="0 1 0"/>
    <limit effort="1000.0" lower="-3.14159265359" upper="3.14159265359" velocity="1745.32925199"/>
    <origin rpy="0 0 3.1415" xyz="0 0 0"/>
    <parent link="head_tilt_link"/>
    <child link="head_base_link"/>
  </joint>
  <link name="head_base_link">
    <visual>
      <geometry>
        <mesh filename="package://inmoov_meshes/meshes/head_base.stl" scale="0.001 0.001 0.001"/>
      </geometry>
      <origin rpy="0 0 0" xyz="0 0 0"/>
      <material name="cframe">
        <color rgba="0.40 0.40 0.40 1"/>
      </material>
    </visual>
    <inertial>
      <mass value="43.50228125"/>
      <inertia ixx="0.025681996" ixy="1.829096875e-05" ixz="-0.00079066275" iyy="0.017327208" iyz="9.602263672e-06" izz="0.03535528"/>
    </inertial>
  </link>
  <link name="head_link">
    <visual>
      <geometry>
        <mesh filename="package://inmoov_meshes/meshes/head.stl" scale="0.001 0.001 0.001"/>
      </geometry>
      <origin rpy="0 0 0" xyz="0 0 0"/>
      <material name="cframe">
        <color rgba="0.40 0.40 0.40 1"/>
      </material>
    </visual>
    <inertial>
      <mass value="120.499460938"/>
      <inertia ixx="0.09250868" ixy="-0.000123085367188" ixz="-0.0078627105" iyy="0.150815008" iyz="0.0002850305625" izz="0.201933552"/>
    </inertial>
  </link>
  <link name="jaw_link">
    <visual>
      <geometry>
        <mesh filename="package://inmoov_meshes/meshes/jaw.stl" scale="0.001 0.001 0.001"/>
      </geometry>
      <origin rpy="0 0 0" xyz="0 0 0"/>
      <material name="ccover">
        <color rgba="0.75 0.75 0.75 1.0"/>
      </material>
    </visual>
    <inertial>
      <mass value="58.767261719"/>
      <inertia ixx="0.147272256" ixy="7.553278125e-05" ixz="0.055060208" iyy="0.134112088" iyz="-1.2159836914e-05" izz="0.156998304"/>
    </inertial>
  </link>
  <link name="skull_link">
    <visual>
      <geometry>
        <mesh filename="package://inmoov_meshes/meshes/skull.stl" scale="0.001 0.001 0.001"/>
      </geometry>
      <origin rpy="0 0 0" xyz="0 0 0"/>
      <material name="ccover">
        <color rgba="0.75 0.75 0.75 1.0"/>
      </material>
    </visual>
    <inertial>
      <mass value="422.3130625"/>
      <inertia ixx="1.82323712" ixy="0.006736614" ixz="0.115768256" iyy="2.48802176" iyz="-0.0004186136875" izz="2.440409856"/>
    </inertial>
  </link>
  <link name="left_ear_link">
    <visual>
      <geometry>
        <mesh filename="package://inmoov_meshes/meshes/earleftv1.stl" scale="0.001 0.001 0.001"/>
      </geometry>
      <origin rpy="0 0 0" xyz="0 0 0"/>
      <material name="cframe">
        <color rgba="0.40 0.40 0.40 1"/>
      </material>
    </visual>
    <inertial>
      <mass value="85.197960938"/>
      <inertia ixx="0.04423034" ixy="-0.001262894" ixz="0.005220882" iyy="0.08046712" iyz="-0.00048412846875" izz="0.04075106"/>
    </inertial>
  </link>
  <link name="right_ear_link">
    <visual>
      <geometry>
        <mesh filename="package://inmoov_meshes/meshes/earrightv1.stl" scale="0.001 0.001 0.001"/>
      </geometry>
      <origin rpy="0 0 0" xyz="0 0 0"/>
      <material name="cframe">
        <color rgba="0.40 0.40 0.40 1"/>
      </material>
    </visual>
    <inertial>
      <mass value="85.17540625"/>
      <inertia ixx="0.044218692" ixy="0.00126241425" ixz="0.0052192235" iyy="0.080448136" iyz="0.00048353196875" izz="0.040740816"/>
    </inertial>
  </link>
  <joint name="head_pan_joint" type="revolute">
    <axis xyz="0 0 1"/>
    <limit effort="1000.0" lower="-3.14159265359" upper="3.14159265359" velocity="1745.32925199"/>
    <origin rpy="0 0 0" xyz="0 0 0.0245"/>
    <parent link="head_base_link"/>
    <child link="head_link"/>
  </joint>
  <joint name="jaw_joint" type="revolute">
    <axis xyz="0 1 0"/>
    <limit effort="1000.0" lower="-3.14159265359" upper="3.14159265359" velocity="1745.32925199"/>
    <origin rpy="0 0.09 0" xyz="0.0375 0.0005 0.0437"/>
    <parent link="head_link"/>
    <child link="jaw_link"/>
  </joint>
  <joint name="skull_joint" type="fixed">
    <origin rpy="0 0 0" xyz="0.044 0 -0.0245"/>
    <parent link="head_link"/>
    <child link="skull_link"/>
  </joint>
  <joint name="left_ear_joint" type="fixed">
    <origin rpy="0 0 0" xyz="0.035 0.056 0.0437"/>
    <parent link="head_link"/>
    <child link="left_ear_link"/>
  </joint>
  <joint name="right_ear_joint" type="fixed">
    <origin rpy="0 0 0" xyz="0.035 -0.056 0.0437"/>
    <parent link="head_link"/>
    <child link="right_ear_link"/>
  </joint>
  <link name="face_link">
    <visual>
      <geometry>
        <mesh filename="package://inmoov_meshes/meshes/face.stl" scale="0.001 0.001 0.001"/>
      </geometry>
      <origin rpy="0 0 0" xyz="0 0 0"/>
      <material name="ccover">
        <color rgba="0.75 0.75 0.75 1.0"/>
      </material>
    </visual>
    <inertial>
      <mass value="46.55903125"/>
      <inertia ixx="0.060878272" ixy="6.9925132812e-05" ixz="0.00126951125" iyy="0.01978544" iyz="1.37124939e-06" izz="0.051128208"/>
    </inertial>
  </link>
  <joint name="eyes_tilt_joint" type="revolute">
    <axis xyz="0 1 0"/>
    <limit effort="1000.0" lower="-3.14159265359" upper="3.14159265359" velocity="1745.32925199"/>
    <origin rpy="0 0 0" xyz="0 0 0"/>
    <parent link="face_link"/>
    <child link="eyesupport_link"/>
  </joint>
  <link name="eyesupport_link">
    <visual>
      <geometry>
        <mesh filename="package://inmoov_meshes/meshes/eyesupport.stl" scale="0.001 0.001 0.001"/>
      </geometry>
      <origin rpy="0 0 0" xyz="0 0 0"/>
      <material name="cframe">
        <color rgba="0.40 0.40 0.40 1"/>
      </material>
    </visual>
    <inertial>
      <mass value="27.550294922"/>
      <inertia ixx="0.02063259" ixy="0.0002853024375" ixz="-0.001400304" iyy="0.016763521" iyz="0.00183966425" izz="0.006981697"/>
    </inertial>
  </link>
  <link name="r_eyesupport_link">
    <visual>
      <geometry>
        <mesh filename="package://inmoov_meshes/meshes/r_eyesupport.stl" scale="0.001 0.001 0.001"/>
      </geometry>
      <origin rpy="0 0 0" xyz="0 0 0"/>
      <material name="cframe">
        <color rgba="0.40 0.40 0.40 1"/>
      </material>
    </visual>
    <inertial>
      <mass value="11.370105469"/>
      <inertia ixx="0.00243239225" ixy="6.936413574e-06" ixz="-1.5166977539e-05" iyy="0.001752612875" iyz="0.0001608714375" izz="0.0008966528125"/>
    </inertial>
  </link>
  <link name="r_camera_link">
    <visual>
      <geometry>
        <mesh filename="package://inmoov_meshes/meshes/camera.stl" scale="0.001 0.001 0.001"/>
      </geometry>
      <origin rpy="0 0 0" xyz="0 0 0"/>
      <material name="ccamera">
        <color rgba="0.1 0.1 0.1 1"/>
      </material>
    </visual>
    <inertial>
      <mass value="2.466067627"/>
      <inertia ixx="0.000240846265625" ixy="-6.7754071e-07" ixz="-4.657491211e-06" iyy="7.5434351562e-05" iyz="-3.045460449e-06" izz="0.000181402265625"/>
    </inertial>
  </link>
  <link name="r_eye_link">
    <visual>
      <geometry>
        <mesh filename="package://inmoov_meshes/meshes/eye.stl" scale="0.001 0.001 0.001"/>
      </geometry>
      <origin rpy="0 0 0" xyz="0 0 0"/>
      <material name="ceyeball">
        <color rgba="0.7 0.7 0.7 1"/>
      </material>
    </visual>
    <inertial>
      <mass value="4.659753906"/>
      <inertia ixx="0.0009137171875" ixy="2.418e-12" ixz="2.11749e-10" iyy="0.0004795756875" iyz="-3.262e-12" izz="0.0004755305"/>
    </inertial>
  </link>
  <link name="r_iris_link">
    <visual>
      <geometry>
        <mesh filename="package://inmoov_meshes/meshes/iris.stl" scale="0.001 0.001 0.001"/>
      </geometry>
      <origin rpy="0 0 0" xyz="0 0 0"/>
      <material name="ciris">
        <color rgba="0.25 0.41 0.88 1"/>
      </material>
    </visual>
    <inertial>
      <mass value="1.026836548"/>
      <inertia ixx="8.5819992188e-05" ixy="-1.07131e-10" ixz="-2.94199e-10" iyy="4.4821710938e-05" iyz="4.19771e-10" izz="4.4822714844e-05"/>
    </inertial>
  </link>
  <joint name="r_camera_joint" type="fixed">
    <origin rpy="0 0 0" xyz="-0.001 0 0"/>
    <parent link="r_eyesupport_link"/>
    <child link="r_camera_link"/>
  </joint>
  <joint name="r_eye_joint" type="fixed">
    <origin rpy="0 0 0" xyz="0.003 0 0"/>
    <parent link="r_eyesupport_link"/>
    <child link="r_eye_link"/>
  </joint>
  <joint name="r_iris_joint" type="fixed">
    <origin rpy="0 0 0" xyz="0.0061 0 0"/>
    <parent link="r_eyesupport_link"/>
    <child link="r_iris_link"/>
  </joint>
  <joint name="eyes_pan_joint" type="revolute">
    <axis xyz="0 0 1"/>
    <limit effort="1000.0" lower="-3.14159265359" upper="3.14159265359" velocity="1745.32925199"/>
    <origin rpy="0 0 0" xyz="0 0.033 -0.0036"/>
    <parent link="eyesupport_link"/>
    <child link="r_eyesupport_link"/>
  </joint>
  <link name="l_eyesupport_link">
    <visual>
      <geometry>
        <mesh filename="package://inmoov_meshes/meshes/l_eyesupport.stl" scale="0.001 0.001 0.001"/>
      </geometry>
      <origin rpy="0 0 0" xyz="0 0 0"/>
      <material name="cframe">
        <color rgba="0.40 0.40 0.40 1"/>
      </material>
    </visual>
    <inertial>
      <mass value="11.370105469"/>
      <inertia ixx="0.00243239225" ixy="-6.936314941e-06" ixz="-1.5166963867e-05" iyy="0.00175261275" iyz="-0.0001608714375" izz="0.0008966526875"/>
    </inertial>
  </link>
  <link name="l_camera_link">
    <visual>
      <geometry>
        <mesh filename="package://inmoov_meshes/meshes/camera.stl" scale="0.001 0.001 0.001"/>
      </geometry>
      <origin rpy="0 0 0" xyz="0 0 0"/>
      <material name="ccamera">
        <color rgba="0.1 0.1 0.1 1"/>
      </material>
    </visual>
    <inertial>
      <mass value="2.466067627"/>
      <inertia ixx="0.000240846265625" ixy="-6.7754071e-07" ixz="-4.657491211e-06" iyy="7.5434351562e-05" iyz="-3.045460449e-06" izz="0.000181402265625"/>
    </inertial>
  </link>
  <link name="l_eye_link">
    <visual>
      <geometry>
        <mesh filename="package://inmoov_meshes/meshes/eye.stl" scale="0.001 0.001 0.001"/>
      </geometry>
      <origin rpy="0 0 0" xyz="0 0 0"/>
      <material name="ceyeball">
        <color rgba="0.7 0.7 0.7 1"/>
      </material>
    </visual>
    <inertial>
      <mass value="4.659753906"/>
      <inertia ixx="0.0009137171875" ixy="2.418e-12" ixz="2.11749e-10" iyy="0.0004795756875" iyz="-3.262e-12" izz="0.0004755305"/>
    </inertial>
  </link>
  <link name="l_iris_link">
    <visual>
      <geometry>
        <mesh filename="package://inmoov_meshes/meshes/iris.stl" scale="0.001 0.001 0.001"/>
      </geometry>
      <origin rpy="0 0 0" xyz="0 0 0"/>
      <material name="ciris">
        <color rgba="0.25 0.41 0.88 1"/>
      </material>
    </visual>
    <inertial>
      <mass value="1.026836548"/>
      <inertia ixx="8.5819992188e-05" ixy="-1.07131e-10" ixz="-2.94199e-10" iyy="4.4821710938e-05" iyz="4.19771e-10" izz="4.4822714844e-05"/>
    </inertial>
  </link>
  <joint name="l_camera_joint" type="fixed">
    <origin rpy="0 0 0" xyz="-0.001 0 0"/>
    <parent link="l_eyesupport_link"/>
    <child link="l_camera_link"/>
  </joint>
  <joint name="l_eye_joint" type="fixed">
    <origin rpy="0 0 0" xyz="0.003 0 0"/>
    <parent link="l_eyesupport_link"/>
    <child link="l_eye_link"/>
  </joint>
  <joint name="l_iris_joint" type="fixed">
    <origin rpy="0 0 0" xyz="0.0061 0 0"/>
    <parent link="l_eyesupport_link"/>
    <child link="l_iris_link"/>
  </joint>
  <joint name="l_eye_pan_joint" type="revolute">
    <axis xyz="0 0 1"/>
    <limit effort="1000.0" lower="-3.14159265359" upper="3.14159265359" velocity="1745.32925199"/>
    <mimic joint="eyes_pan_joint" multiplier="1" offset="0"/>
    <origin rpy="0 0 0" xyz="0 -0.033 -0.0036"/>
    <parent link="eyesupport_link"/>
    <child link="l_eyesupport_link"/>
  </joint>
  <joint name="face_joint" type="fixed">
    <origin rpy="0 0 0" xyz="0.0637 0 0.079"/>
    <parent link="skull_link"/>
    <child link="face_link"/>
  </joint>
  <link name="r_shoulder_base_link">
    <visual>
      <geometry>
        <mesh filename="package://inmoov_meshes/meshes/r_shoulder_base.stl" scale="0.001 0.001 0.001"/>
      </geometry>
      <origin rpy="0 0 0" xyz="0 0 0"/>
      <material name="cframe">
        <color rgba="0.40 0.40 0.40 1"/>
      </material>
    </visual>
    <inertial>
      <mass value="266.52696875"/>
      <inertia ixx="0.350410112" ixy="-0.0057351625" ixz="-0.011193818" iyy="0.3908856" iyz="0.045447476" izz="0.271458688"/>
    </inertial>
  </link>
  <link name="r_shoulder_link">
    <visual>
      <geometry>
        <mesh filename="package://inmoov_meshes/meshes/r_shoulder.stl" scale="0.001 0.001 0.001"/>
      </geometry>
      <origin rpy="0 0 0" xyz="0 0 0"/>
      <material name="cframe">
        <color rgba="0.40 0.40 0.40 1"/>
      </material>
    </visual>
    <inertial>
      <mass value="322.44334375"/>
      <inertia ixx="0.60134592" ixy="0.00343772975" ixz="-0.011761917" iyy="0.473865856" iyz="-0.114277" izz="0.500951584"/>
    </inertial>
  </link>
  <link name="r_bicep_link">
    <visual>
      <geometry>
        <mesh filename="package://inmoov_meshes/meshes/bicep.stl" scale="0.001 0.001 0.001"/>
      </geometry>
      <origin rpy="0 0 0" xyz="0 0 0"/>
      <material name="cframe">
        <color rgba="0.40 0.40 0.40 1"/>
      </material>
    </visual>
    <inertial>
      <mass value="281.91265625"/>
      <inertia ixx="1.283355392" ixy="-0.000200782203125" ixz="-0.224559104" iyy="1.399255168" iyz="0.0006545236875" izz="0.416621216"/>
    </inertial>
  </link>
  <link name="r_bicepcover_link">
    <visual>
      <geometry>
        <mesh filename="package://inmoov_meshes/meshes/bicepcover.stl" scale="0.001 0.001 0.001"/>
      </geometry>
      <origin rpy="0 0 0" xyz="0 0 0"/>
      <material name="ccover">
        <color rgba="0.75 0.75 0.75 1.0"/>
      </material>
    </visual>
    <inertial>
      <mass value="176.269609375"/>
      <inertia ixx="0.536349632" ixy="0.0009665334375" ixz="-0.069306768" iyy="0.625805568" iyz="0.0005666358125" izz="0.44191648"/>
    </inertial>
  </link>
  <link name="r_forearm_link">
    <visual>
      <geometry>
        <mesh filename="package://inmoov_meshes/meshes/r_forearm.stl" scale="0.001 0.001 0.001"/>
      </geometry>
      <origin rpy="0 0 0" xyz="0.001 0 0"/>
      <material name="ccover">
        <color rgba="0.75 0.75 0.75 1.0"/>
      </material>
    </visual>
    <inertial>
      <mass value="401.76659375"/>
      <inertia ixx="3.242307584" ixy="0.050011216" ixz="-0.14318512" iyy="3.24251008" iyz="0.086288976" izz="0.58458784"/>
    </inertial>
  </link>
  <joint name="r_shoulder_lift_joint" type="revolute">
    <axis xyz="0 1 0"/>
    <limit effort="1000.0" lower="-3.14159265359" upper="3.14159265359" velocity="1745.32925199"/>
    <origin rpy="0 0 0" xyz="0 -0.012 -0.04"/>
    <parent link="r_shoulder_base_link"/>
    <child link="r_shoulder_link"/>
  </joint>
  <joint name="r_upper_arm_roll_joint" type="revolute">
    <axis xyz="0 0 1"/>
    <limit effort="1000.0" lower="-3.14159265359" upper="3.14159265359" velocity="1745.32925199"/>
    <origin rpy="0 0 0" xyz="0 -0.066 -0.060"/>
    <parent link="r_shoulder_link"/>
    <child link="r_bicep_link"/>
  </joint>
  <joint name="r_elbow_flex_joint" type="revolute">
    <axis xyz="0 1 0"/>
    <limit effort="1000.0" lower="-3.14159265359" upper="3.14159265359" velocity="1745.32925199"/>
    <origin rpy="0 0 0" xyz="-0.0278 0 -0.2235"/>
    <parent link="r_bicep_link"/>
    <child link="r_forearm_link"/>
  </joint>
  <joint name="r_bicepcover_joint" type="fixed">
    <origin rpy="0 0 0" xyz="0 0 0"/>
    <parent link="r_bicep_link"/>
    <child link="r_bicepcover_link"/>
  </joint>
  <joint name="r_shoulder_out_joint" type="revolute">
    <axis xyz="1 0 0"/>
    <limit effort="1000.0" lower="-3.14159265359" upper="3.14159265359" velocity="1745.32925199"/>
    <origin rpy="0 0 0" xyz="0 -0.143 0.298"/>
    <parent link="torso_link"/>
    <child link="r_shoulder_base_link"/>
  </joint>
  <link name="r_hand_link">
    <visual>
      <geometry>
        <cylinder length="0.11" radius="0.06"/>
      </geometry>
      <origin rpy="0 0 0" xyz="0 0 0.055"/>
      <material name="cbase">
        <color rgba="0.1 0.1 0.1 1"/>
      </material>
    </visual>
  </link>
  <joint name="r_wrist_roll_joint" type="revolute">
    <axis xyz="0 0 1"/>
    <limit effort="1000.0" lower="-3.14159265359" upper="3.14159265359" velocity="1745.32925199"/>
    <origin rpy="0 0 0" xyz="-0.0144 0.01  -0.2885"/>
    <parent link="r_forearm_link"/>
    <child link="r_hand_link"/>
  </joint>
  <link name="l_shoulder_base_link">
    <visual>
      <geometry>
        <mesh filename="package://inmoov_meshes/meshes/l_shoulder_base.stl" scale="0.001 0.001 0.001"/>
      </geometry>
      <origin rpy="0 0 0" xyz="0 0 0"/>
      <material name="cframe">
        <color rgba="0.40 0.40 0.40 1"/>
      </material>
    </visual>
    <inertial>
      <mass value="266.52696875"/>
      <inertia ixx="0.35041024" ixy="0.0057351615" ixz="-0.011193821" iyy="0.390885728" iyz="-0.045447508" izz="0.27145872"/>
    </inertial>
  </link>
  <link name="l_shoulder_link">
    <visual>
      <geometry>
        <mesh filename="package://inmoov_meshes/meshes/l_shoulder.stl" scale="0.001 0.001 0.001"/>
      </geometry>
      <origin rpy="0 0 0" xyz="0 0 0"/>
      <material name="cframe">
        <color rgba="0.40 0.40 0.40 1"/>
      </material>
    </visual>
    <inertial>
      <mass value="322.44334375"/>
      <inertia ixx="0.601346048" ixy="-0.003437744" ixz="-0.011761914" iyy="0.473865952" iyz="0.11427704" izz="0.50095152"/>
    </inertial>
  </link>
  <link name="l_bicep_link">
    <visual>
      <geometry>
        <mesh filename="package://inmoov_meshes/meshes/bicep.stl" scale="0.001 0.001 0.001"/>
      </geometry>
      <origin rpy="0 0 0" xyz="0 0 0"/>
      <material name="cframe">
        <color rgba="0.40 0.40 0.40 1"/>
      </material>
    </visual>
    <inertial>
      <mass value="281.91265625"/>
      <inertia ixx="1.283355392" ixy="-0.000200782203125" ixz="-0.224559104" iyy="1.399255168" iyz="0.0006545236875" izz="0.416621216"/>
    </inertial>
  </link>
  <link name="l_bicepcover_link">
    <visual>
      <geometry>
        <mesh filename="package://inmoov_meshes/meshes/bicepcover.stl" scale="0.001 0.001 0.001"/>
      </geometry>
      <origin rpy="0 0 0" xyz="0 0 0"/>
      <material name="ccover">
        <color rgba="0.75 0.75 0.75 1.0"/>
      </material>
    </visual>
    <inertial>
      <mass value="176.269609375"/>
      <inertia ixx="0.536349632" ixy="0.0009665334375" ixz="-0.069306768" iyy="0.625805568" iyz="0.0005666358125" izz="0.44191648"/>
    </inertial>
  </link>
  <link name="l_forearm_link">
    <visual>
      <geometry>
        <mesh filename="package://inmoov_meshes/meshes/l_forearm.stl" scale="0.001 0.001 0.001"/>
      </geometry>
      <origin rpy="0 0 0" xyz="-0.001 0 0"/>
      <material name="ccover">
        <color rgba="0.75 0.75 0.75 1.0"/>
      </material>
    </visual>
    <inertial>
      <mass value="401.76659375"/>
      <inertia ixx="3.242308096" ixy="-0.050011216" ixz="-0.143185152" iyy="3.242510848" iyz="-0.086288992" izz="0.58458784"/>
    </inertial>
  </link>
  <joint name="l_shoulder_lift_joint" type="revolute">
    <axis xyz="0 1 0"/>
    <limit effort="1000.0" lower="-3.14159265359" upper="3.14159265359" velocity="1745.32925199"/>
    <origin rpy="0 0 0" xyz="0 0.012 -0.04"/>
    <parent link="l_shoulder_base_link"/>
    <child link="l_shoulder_link"/>
  </joint>
  <joint name="l_upper_arm_roll_joint" type="revolute">
    <axis xyz="0 0 1"/>
    <limit effort="1000.0" lower="-3.14159265359" upper="3.14159265359" velocity="1745.32925199"/>
    <origin rpy="0 0 0" xyz="0 0.066 -0.060"/>
    <parent link="l_shoulder_link"/>
    <child link="l_bicep_link"/>
  </joint>
  <joint name="l_elbow_flex_joint" type="revolute">
    <axis xyz="0 1 0"/>
    <limit effort="1000.0" lower="-3.14159265359" upper="3.14159265359" velocity="1745.32925199"/>
    <origin rpy="0 0 0" xyz="-0.0278 0 -0.2235"/>
    <parent link="l_bicep_link"/>
    <child link="l_forearm_link"/>
  </joint>
  <joint name="l_bicepcover_joint" type="fixed">
    <origin rpy="0 0 0" xyz="0 0 0"/>
    <parent link="l_bicep_link"/>
    <child link="l_bicepcover_link"/>
  </joint>
  <joint name="l_shoulder_out_joint" type="revolute">
    <axis xyz="1 0 0"/>
    <limit effort="1000.0" lower="-3.14159265359" upper="3.14159265359" velocity="1745.32925199"/>
    <origin rpy="0 0 0" xyz="0 0.143 0.298"/>
    <parent link="torso_link"/>
    <child link="l_shoulder_base_link"/>
  </joint>
  <link name="l_hand_link">
    <visual>
      <geometry>
        <cylinder length="0.11" radius="0.06"/>
      </geometry>
      <origin rpy="0 0 0" xyz="0 0 0.055"/>
      <material name="cbase">
        <color rgba="0.1 0.1 0.1 1"/>
      </material>
    </visual>
  </link>
  <joint name="l_wrist_roll_joint" type="revolute">
    <axis xyz="0 0 1"/>
    <limit effort="1000.0" lower="-3.14159265359" upper="3.14159265359" velocity="1745.32925199"/>
    <origin rpy="0 0 0" xyz="-0.0144 -0.01  -0.2885"/>
    <parent link="l_forearm_link"/>
    <child link="l_hand_link"/>
  </joint>
</robot>

