<?xml version="1.0" ?>
<!-- =================================================================================== -->
<!-- |    This document was autogenerated by xacro from inmoov_shadow_hand_v2.urdf.xacro | -->
<!-- |    EDITING THIS FILE BY HAND IS NOT RECOMMENDED                                 | -->
<!-- =================================================================================== -->
<robot name="inmoov_arm">
  <!--xacro:property name="pi" value="3.1415926539"/-->
  <!-- usage: e.g. ${M_PI/4} -->
  <material name="Blue">
    <color rgba="0.0 0.0 0.8 1.0"/>
  </material>
  <material name="Green">
    <color rgba="0.0 0.8 0.0 1.0"/>
  </material>
  <material name="BiotacGreen">
    <color rgba="0.31 0.85 0.42 1.0"/>
  </material>
  <material name="Grey">
    <color rgba="0.2 0.2 0.2 1.0"/>
  </material>
  <material name="LightGrey">
    <color rgba="0.6 0.6 0.6 1.0"/>
  </material>
  <material name="Red">
    <color rgba="0.8 0.0 0.0 1.0"/>
  </material>
  <material name="White">
    <color rgba="1.0 1.0 1.0 1.0"/>
  </material>

  <link name="r_shoulder_link">
    <visual>
      <geometry>
        <mesh filename="package://inmoov_meshes/meshes/r_shoulder.stl" scale="0.001 0.001 0.001"/>
      </geometry>
      <origin rpy="0 0 0" xyz="0 0 0"/>
      <material name="cframe">
        <color rgba="0.40 0.40 0.40 1"/>
      </material>
    </visual>
    <inertial>
      <mass value="1"/>
      <inertia ixx="1" ixy="0" ixz="0" iyy="1" iyz="0" izz="1"/>
    </inertial>
  </link>
  <link name="r_bicep_link_aux_0">
    <inertial>
      <origin rpy="0 0 0" xyz="0 0 0"/>
      <mass value="1.00"/>
      <inertia ixx="1.000" ixy="0" ixz="0" iyy="1.000" iyz="0" izz="1.000"/>
    </inertial>
  </link>
  <link name="r_bicep_link_aux_1">
    <inertial>
      <origin rpy="0 0 0" xyz="0 0 0"/>
      <mass value="1.00"/>
      <inertia ixx="1.000" ixy="0" ixz="0" iyy="1.000" iyz="0" izz="1.000"/>
    </inertial>
  </link>
  <link name="r_bicep_link">
    <visual>
      <geometry>
        <mesh filename="package://inmoov_meshes/meshes/bicep.stl" scale="0.001 0.001 0.001"/>
      </geometry>
      <origin rpy="0 0 0" xyz="0 0 0"/>
      <material name="cframe">
        <color rgba="0.40 0.40 0.40 1"/>
      </material>
    </visual>
    <inertial>
      <mass value="1"/>
      <inertia ixx="1" ixy="0" ixz="0" iyy="1" iyz="0" izz="1"/>
    </inertial>
  </link>
  <link name="r_forearm_link_aux">
    <inertial>
      <origin rpy="0 0 0" xyz="0 0 0"/>
      <mass value="1.00"/>
      <inertia ixx="1.000" ixy="0" ixz="0" iyy="1.000" iyz="0" izz="1.000"/>
    </inertial>
  </link>
  <link name="r_forearm_link">
    <visual>
      <geometry>
        <mesh filename="package://inmoov_meshes/meshes/r_forearm.stl" scale="0.001 0.001 0.001"/>
      </geometry>
      <origin rpy="0 0 0" xyz="0.001 0 0"/>
      <material name="ccover">
        <color rgba="0.75 0.75 0.75 1.0"/>
      </material>
    </visual>
    <inertial>
      <mass value="1"/>
      <inertia ixx="1" ixy="0" ixz="0" iyy="1" iyz="0" izz="1"/>
    </inertial>
  </link>

  <joint name="r_shoulder_out_joint" type="revolute">
    <axis xyz="1 0 0"/>
    <limit effort="1000.0" lower="-1.57079632679" upper="1.57079632679" velocity="1745.32925199"/>
    <origin rpy="0 0 0" xyz="0 -0.066 -0.06"/>
    <parent link="r_shoulder_link"/>
    <child link="r_bicep_link_aux_0"/>
  </joint>
  <joint name="r_shoulder_lift_joint" type="revolute">
    <axis xyz="0 1 0"/>
    <limit effort="1000.0" lower="-1.57079632679" upper="1.57079632679" velocity="1745.32925199"/>
    <origin rpy="0 0 0" xyz="0 0 0"/>
    <parent link="r_bicep_link_aux_0"/>
    <child link="r_bicep_link_aux_1"/>
  </joint>
  <joint name="r_upper_arm_roll_joint" type="revolute">
    <axis xyz="0 0 1"/>
    <limit effort="1000.0" lower="-1.57079632679" upper="1.57079632679" velocity="1745.32925199"/>
    <origin rpy="0 0 0" xyz="0 0 0"/>
    <parent link="r_bicep_link_aux_1"/>
    <child link="r_bicep_link"/>
  </joint>
  <joint name="r_elbow_flex_joint" type="revolute">
    <axis xyz="0 1 0"/>
    <limit effort="1000.0" lower="-3.14159265359" upper="0.0" velocity="1745.32925199"/>
    <origin rpy="0 0 0" xyz="-0.03 0 -0.225"/>
    <!--TODO: why there is a -0.03 here-->
    <parent link="r_bicep_link"/>
    <child link="r_forearm_link_aux"/>
  </joint>
  <joint name="r_elbow_roll_joint" type="revolute">
    <axis xyz="0 0 1"/>
    <limit effort="1000.0" lower="-1.57079632679" upper="1.57079632679" velocity="1745.32925199"/>
    <origin rpy="0 0 0" xyz="0.0 0 0.0"/>
    <parent link="r_forearm_link_aux"/>
    <child link="r_forearm_link"/>
  </joint>
  <!--<joint name="r_bicepcover_joint" type="fixed">-->
    <!--<origin rpy="0 0 0" xyz="0 0 0"/>-->
    <!--<parent link="r_bicep_link"/>-->
    <!--<child link="r_bicepcover_link"/>-->
  <!--</joint>-->

  <!-- shadow hand -->
  <link name="r_hand_link">
    <inertial>
      <origin rpy="0 0 0" xyz="0 0 0"/>
      <mass value="0.00"/>
      <inertia ixx="0.000" ixy="0" ixz="0" iyy="0.000" iyz="0" izz="0.000"/>
    </inertial>
  </link>
  <joint name="r_wrist_roll_joint" type="fixed">
    <parent link="r_forearm_link"/>
    <child link="r_hand_link"/>
    <origin rpy="3.14159265359 0 0" xyz="-0.015 0.01 -0.3"/>
  </joint>

  <!--TODO: longer than upperarm odd.-->
  <link name="rh_wrist">
    <inertial>
      <origin rpy="0 0 0" xyz="0 0 0.029"/>
      <mass value="1"/>
      <inertia ixx="1" ixy="0.0" ixz="0.0" iyy="1" iyz="0.0" izz="1"/>
    </inertial>
    <visual>
      <origin rpy="0 0 0" xyz="0 0 0"/>
      <geometry name="rh_wrist_visual">
        <mesh filename="package://sr_description/hand/model/wrist.dae" scale="0.001 0.001 0.001"/>
      </geometry>
      <material name="LightGrey"/>
    </visual>
  </link>
  <joint name="rh_WRJ2" type="revolute">
    <parent link="r_hand_link"/>
    <child link="rh_wrist"/>
    <origin rpy="0 0 0" xyz="0 0.0 0.0"/>
    <!-- this is the wrist adduction -->
    <axis xyz="0 1.0 0"/>
    <limit effort="1000" lower="-1.0471975512" upper="1.0471975512" velocity="200.0"/>
  </joint>

  <link name="rh_palm_aux">
    <inertial>
      <origin rpy="0 0 0" xyz="0 0 0"/>
      <mass value="0.00"/>
      <inertia ixx="0.000" ixy="0" ixz="0" iyy="0.000" iyz="0" izz="0.000"/>
    </inertial>
  </link>
  <joint name="rh_WRJ1" type="revolute">
    <parent link="rh_wrist"/>
    <child link="rh_palm_aux"/>
    <origin rpy="0 0 0" xyz="0 0 0.03"/>
    <axis xyz="1 0 0"/>
    <!-- this is the wrist flexion -->
    <limit effort="1000" lower="-1.57079632679" upper="1.57079632679" velocity="200.0"/>
  </joint>

  <link name="rh_palm">
    <inertial>
      <origin rpy="0 0 0" xyz="0 0 0.035"/>
      <mass value="1"/>
      <inertia ixx="1" ixy="0.0" ixz="0.0" iyy="1" iyz="0.0" izz="1"/>
    </inertial>
    <visual>
      <origin rpy="0 0 0" xyz="0 0 0"/>
      <geometry name="rh_palm_visual">
        <mesh filename="package://sr_description/hand/model/palm.dae" scale="0.001 0.001 0.001"/>
      </geometry>
      <material name="Grey"/>
    </visual>
    <collision>
      <origin rpy="0 0 0" xyz="0.011 0.0085 0.038"/>
      <geometry name="rh_palm_collision_geom">
        <box size="0.062 0.007 0.098"/>
      </geometry>
    </collision>
    <collision>
      <origin rpy="0 0 0" xyz="-0.002 -0.0035 0.038"/>
      <geometry>
        <box size="0.036 0.017 0.098"/>
      </geometry>
    </collision>
    <!-- palm complement below first finger -->
    <collision>
      <origin rpy="0 0 0" xyz="0.029 -0.0035 0.082"/>
      <geometry>
        <box size="0.026 0.017 0.010"/>
      </geometry>
    </collision>
    <collision>
      <origin rpy="0.2 0 0.25" xyz="0.0265 -0.001 0.070"/>
      <geometry>
        <box size="0.026 0.014 0.018"/>
      </geometry>
    </collision>
    <!-- thumb pulp side -->
    <collision>
      <origin rpy="0 0 0" xyz="0.0315 -0.0085 0.001"/>
      <geometry>
        <box size="0.021 0.027 0.024"/>
      </geometry>
    </collision>
    <!-- thumb pulp central -->
    <collision>
      <origin rpy="0 0 -0.48" xyz="0.0125 -0.015 0.009"/>
      <geometry>
        <box size="0.022 0.005 0.040"/>
      </geometry>
    </collision>
    <!-- above middle finger-->
    <collision>
      <origin rpy="0 0 0" xyz="0.011 0 0.089"/>
      <geometry>
        <box size="0.018 0.024 0.004"/>
      </geometry>
    </collision>
    <!-- metacarpal side-->
    <collision>
      <origin rpy="0 0 0" xyz="-0.03 0 0.009"/>
      <geometry>
        <box size="0.020 0.024 0.040"/>
      </geometry>
    </collision>
  </link>

  <!--TODO: different from hand only -->
  <joint name="rh_palm_aux_joint" type="fixed">
    <origin rpy="0 0 0" xyz="0 0.0 0.0"/>
    <parent link="rh_palm_aux"/>
    <child link="rh_palm"/>
  </joint>

  <!--TODO: 5*4+2 segments-->
  <link name="rh_ffknuckle">
    <inertial>
      <origin rpy="0 0 0" xyz="0 0 0"/>
      <mass value="1"/>
      <inertia ixx="1" ixy="0.0" ixz="0.0" iyy="1" iyz="0.0" izz="1"/>
    </inertial>
    <visual>
      <origin rpy="0 0 0" xyz="0 0 0.0005"/>
      <geometry name="rh_ffknuckle_visual">
        <mesh filename="package://sr_description/hand/model/knuckle.dae" scale="0.001 0.001 0.001"/>
      </geometry>
      <material name="LightGrey"/>
    </visual>
    <collision>
      <origin rpy="0 1.5708 0" xyz="0 0 0"/>
      <geometry name="rh_ffknuckle_collision_geom">
        <cylinder length="0.014" radius="0.007"/>
      </geometry>
    </collision>
  </link>
  <joint name="rh_FFJ4" type="fixed">
    <parent link="rh_palm"/>
    <child link="rh_ffknuckle"/>
    <!--<origin xyz="0.033 0 0.095" rpy="0 0 0" />-->
    <origin rpy="0 0 0" xyz="0.033 0 0.095"/>
    <!--<axis xyz="0 -1.0 0"/>-->
    <!--<limit effort="2" lower="-0.349065850399" upper="0.349065850399" velocity="2.0"/>-->
    <!--<dynamics damping="0.1"/>-->
  </joint>
  <link name="rh_ffproximal">
    <inertial>
      <origin xyz="0 0 0.0225"/>
      <mass value="1"/>
      <inertia ixx="1" ixy="0.0" ixz="0.0" iyy="1" iyz="0.0" izz="1"/>
    </inertial>
    <visual>
      <origin rpy="0 0 0" xyz="0 0 0"/>
      <geometry name="rh_ffproximal_visual">
        <mesh filename="package://sr_description/hand/model/F3.dae" scale="0.001 0.001 0.001"/>
      </geometry>
      <material name="Grey"/>
    </visual>
    <collision>
      <origin rpy="0 0 0" xyz="0 0 0.025"/>
      <geometry name="rh_ffproximal_collision_geom">
        <cylinder length="0.040" radius="0.007"/>
      </geometry>
    </collision>
  </link>
  <joint name="rh_FFJ3" type="revolute">
    <parent link="rh_ffknuckle"/>
    <child link="rh_ffproximal"/>
    <origin rpy="0 0 0" xyz="0 0 0"/>
    <axis xyz="1 0 0"/>
    <limit effort="2" lower="0" upper="1.57079632679" velocity="2.0"/>
    <dynamics damping="0.1"/>
  </joint>
  <link name="rh_ffmiddle">
    <inertial>
      <origin rpy="0 0 0" xyz="0 0 0.0125"/>
      <mass value="1"/>
      <inertia ixx="1" ixy="0.0" ixz="0.0" iyy="1" iyz="0.0" izz="1"/>
    </inertial>
    <visual>
      <origin rpy="0 0 0" xyz="0 0 0"/>
      <geometry name="rh_ffmiddle_visual">
        <mesh filename="package://sr_description/hand/model/F2.dae" scale="0.001 0.001 0.001"/>
      </geometry>
      <material name="Grey"/>
    </visual>
    <collision>
      <origin rpy="0 0 0" xyz="0 0 0.0125"/>
      <geometry name="rh_ffmiddle_collision_geom">
        <cylinder length="0.025" radius="0.007"/>
      </geometry>
    </collision>
    <collision>
      <origin rpy="0 0 0" xyz="0 0 0.0"/>
      <geometry>
        <sphere radius="0.007"/>
      </geometry>
    </collision>
    <collision>
      <origin rpy="0 0 0" xyz="0 0 0.025"/>
      <geometry>
        <sphere radius="0.007"/>
      </geometry>
    </collision>
  </link>
  <joint name="rh_FFJ2" type="revolute">
    <parent link="rh_ffproximal"/>
    <child link="rh_ffmiddle"/>
    <origin rpy="0 0 0" xyz="0 0 0.045"/>
    <axis xyz="1 0 0"/>
    <limit effort="2" lower="0" upper="1.57079632679" velocity="2.0"/>
    <dynamics damping="0.1"/>
  </joint>
  <link name="rh_ffdistal">
    <inertial>
      <origin xyz="0 0 0.012"/>
      <mass value="1"/>
      <inertia ixx="1" ixy="0.0" ixz="0.0" iyy="1" iyz="0.0" izz="1"/>
    </inertial>
    <visual>
      <origin rpy="0 0 0" xyz="0 0 0"/>
      <geometry name="rh_ffdistal_visual">
        <!-- Standard distal  -->
        <mesh filename="package://sr_description/hand/model/F1.dae" scale="0.001 0.001 0.001"/>
      </geometry>
      <material name="Grey"/>
    </visual>
    <collision>
      <origin rpy="0 0 0" xyz="0 0 0"/>
      <geometry name="rh_ffdistal_collision_geom">
        <!-- Standard distal  -->
        <mesh filename="package://sr_description/hand/model/F1.dae" scale="0.001 0.001 0.001"/>
      </geometry>
    </collision>
  </link>
  <joint name="rh_FFJ1" type="revolute">
    <parent link="rh_ffmiddle"/>
    <child link="rh_ffdistal"/>
    <origin rpy="0 0 0" xyz="0 0 0.025"/>
    <axis xyz="1 0 0"/>
    <!-- standard distal joint -->
    <limit effort="2" lower="0" upper="1.57079632679" velocity="2.0"/>
    <dynamics damping="0.1"/>
  </joint>

  <link name="rh_mfknuckle">
    <inertial>
      <origin rpy="0 0 0" xyz="0 0 0"/>
      <mass value="1"/>
      <inertia ixx="1" ixy="0.0" ixz="0.0" iyy="1" iyz="0.0" izz="1"/>
    </inertial>
    <visual>
      <origin rpy="0 0 0" xyz="0 0 0.0005"/>
      <geometry name="rh_mfknuckle_visual">
        <mesh filename="package://sr_description/hand/model/knuckle.dae" scale="0.001 0.001 0.001"/>
      </geometry>
      <material name="LightGrey"/>
    </visual>
    <collision>
      <origin rpy="0 1.5708 0" xyz="0 0 0"/>
      <geometry name="rh_mfknuckle_collision_geom">
        <cylinder length="0.014" radius="0.007"/>
      </geometry>
    </collision>
  </link>
  <joint name="rh_MFJ4" type="fixed">
    <parent link="rh_palm"/>
    <child link="rh_mfknuckle"/>
    <!--<origin xyz="0.033 0 0.095" rpy="0 0 0" />-->
    <origin rpy="0 0 0" xyz="0.011 0 0.099"/>
    <!--<axis xyz="0 -1.0 0"/>-->
    <!--<limit effort="2" lower="-0.349065850399" upper="0.349065850399" velocity="2.0"/>-->
    <!--<dynamics damping="0.1"/>-->
  </joint>
  <link name="rh_mfproximal">
    <inertial>
      <origin xyz="0 0 0.0225"/>
      <mass value="1"/>
      <inertia ixx="1" ixy="0.0" ixz="0.0" iyy="1" iyz="0.0" izz="1"/>
    </inertial>
    <visual>
      <origin rpy="0 0 0" xyz="0 0 0"/>
      <geometry name="rh_mfproximal_visual">
        <mesh filename="package://sr_description/hand/model/F3.dae" scale="0.001 0.001 0.001"/>
      </geometry>
      <material name="Grey"/>
    </visual>
    <collision>
      <origin rpy="0 0 0" xyz="0 0 0.025"/>
      <geometry name="rh_mfproximal_collision_geom">
        <cylinder length="0.040" radius="0.007"/>
      </geometry>
    </collision>
  </link>
  <joint name="rh_MFJ3" type="revolute">
    <parent link="rh_mfknuckle"/>
    <child link="rh_mfproximal"/>
    <origin rpy="0 0 0" xyz="0 0 0"/>
    <axis xyz="1 0 0"/>
    <limit effort="2" lower="0" upper="1.57079632679" velocity="2.0"/>
    <dynamics damping="0.1"/>
  </joint>
  <link name="rh_mfmiddle">
    <inertial>
      <origin rpy="0 0 0" xyz="0 0 0.0125"/>
      <mass value="1"/>
      <inertia ixx="1" ixy="0.0" ixz="0.0" iyy="1" iyz="0.0" izz="1"/>
    </inertial>
    <visual>
      <origin rpy="0 0 0" xyz="0 0 0"/>
      <geometry name="rh_mfmiddle_visual">
        <mesh filename="package://sr_description/hand/model/F2.dae" scale="0.001 0.001 0.001"/>
      </geometry>
      <material name="Grey"/>
    </visual>
    <collision>
      <origin rpy="0 0 0" xyz="0 0 0.0125"/>
      <geometry name="rh_mfmiddle_collision_geom">
        <cylinder length="0.025" radius="0.007"/>
      </geometry>
    </collision>
    <collision>
      <origin rpy="0 0 0" xyz="0 0 0.0"/>
      <geometry>
        <sphere radius="0.007"/>
      </geometry>
    </collision>
    <collision>
      <origin rpy="0 0 0" xyz="0 0 0.025"/>
      <geometry>
        <sphere radius="0.007"/>
      </geometry>
    </collision>
  </link>
  <joint name="rh_MFJ2" type="revolute">
    <parent link="rh_mfproximal"/>
    <child link="rh_mfmiddle"/>
    <origin rpy="0 0 0" xyz="0 0 0.045"/>
    <axis xyz="1 0 0"/>
    <limit effort="2" lower="0" upper="1.57079632679" velocity="2.0"/>
    <dynamics damping="0.1"/>
  </joint>
  <link name="rh_mfdistal">
    <inertial>
      <origin xyz="0 0 0.012"/>
      <mass value="1"/>
      <inertia ixx="1" ixy="0.0" ixz="0.0" iyy="1" iyz="0.0" izz="1"/>
    </inertial>
    <visual>
      <origin rpy="0 0 0" xyz="0 0 0"/>
      <geometry name="rh_mfdistal_visual">
        <!-- Standard distal  -->
        <mesh filename="package://sr_description/hand/model/F1.dae" scale="0.001 0.001 0.001"/>
      </geometry>
      <material name="Grey"/>
    </visual>
    <collision>
      <origin rpy="0 0 0" xyz="0 0 0"/>
      <geometry name="rh_mfdistal_collision_geom">
        <!-- Standard distal  -->
        <mesh filename="package://sr_description/hand/model/F1.dae" scale="0.001 0.001 0.001"/>
      </geometry>
    </collision>
  </link>
  <joint name="rh_MFJ1" type="revolute">
    <parent link="rh_mfmiddle"/>
    <child link="rh_mfdistal"/>
    <origin rpy="0 0 0" xyz="0 0 0.025"/>
    <axis xyz="1 0 0"/>
    <!-- standard distal joint -->
    <limit effort="2" lower="0" upper="1.57079632679" velocity="2.0"/>
    <dynamics damping="0.1"/>
  </joint>

  <link name="rh_rfknuckle">
    <inertial>
      <origin rpy="0 0 0" xyz="0 0 0"/>
      <mass value="1"/>
      <inertia ixx="1" ixy="0.0" ixz="0.0" iyy="1" iyz="0.0" izz="1"/>
    </inertial>
    <visual>
      <origin rpy="0 0 0" xyz="0 0 0.0005"/>
      <geometry name="rh_rfknuckle_visual">
        <mesh filename="package://sr_description/hand/model/knuckle.dae" scale="0.001 0.001 0.001"/>
      </geometry>
      <material name="LightGrey"/>
    </visual>
    <collision>
      <origin rpy="0 1.5708 0" xyz="0 0 0"/>
      <geometry name="rh_rfknuckle_collision_geom">
        <cylinder length="0.014" radius="0.007"/>
      </geometry>
    </collision>
  </link>
  <joint name="rh_RFJ4" type="fixed">
    <parent link="rh_palm"/>
    <child link="rh_rfknuckle"/>
    <!--<origin xyz="0.033 0 0.095" rpy="0 0 0" />-->
    <origin rpy="0 0 0" xyz="-0.011 0 0.095"/>
    <!--<axis xyz="0 1.0 0"/>-->
    <!--<limit effort="2" lower="-0.349065850399" upper="0.349065850399" velocity="2.0"/>-->
    <!--<dynamics damping="0.1"/>-->
  </joint>
  <link name="rh_rfproximal">
    <inertial>
      <origin xyz="0 0 0.0225"/>
      <mass value="1"/>
      <inertia ixx="1" ixy="0.0" ixz="0.0" iyy="1" iyz="0.0" izz="1"/>
    </inertial>
    <visual>
      <origin rpy="0 0 0" xyz="0 0 0"/>
      <geometry name="rh_rfproximal_visual">
        <mesh filename="package://sr_description/hand/model/F3.dae" scale="0.001 0.001 0.001"/>
      </geometry>
      <material name="Grey"/>
    </visual>
    <collision>
      <origin rpy="0 0 0" xyz="0 0 0.025"/>
      <geometry name="rh_rfproximal_collision_geom">
        <cylinder length="0.040" radius="0.007"/>
      </geometry>
    </collision>
  </link>
  <joint name="rh_RFJ3" type="revolute">
    <parent link="rh_rfknuckle"/>
    <child link="rh_rfproximal"/>
    <origin rpy="0 0 0" xyz="0 0 0"/>
    <axis xyz="1 0 0"/>
    <limit effort="2" lower="0" upper="1.57079632679" velocity="2.0"/>
    <dynamics damping="0.1"/>
  </joint>
  <link name="rh_rfmiddle">
    <inertial>
      <origin rpy="0 0 0" xyz="0 0 0.0125"/>
      <mass value="1"/>
      <inertia ixx="1" ixy="0.0" ixz="0.0" iyy="1" iyz="0.0" izz="1"/>
    </inertial>
    <visual>
      <origin rpy="0 0 0" xyz="0 0 0"/>
      <geometry name="rh_rfmiddle_visual">
        <mesh filename="package://sr_description/hand/model/F2.dae" scale="0.001 0.001 0.001"/>
      </geometry>
      <material name="Grey"/>
    </visual>
    <collision>
      <origin rpy="0 0 0" xyz="0 0 0.0125"/>
      <geometry name="rh_rfmiddle_collision_geom">
        <cylinder length="0.025" radius="0.007"/>
      </geometry>
    </collision>
    <collision>
      <origin rpy="0 0 0" xyz="0 0 0.0"/>
      <geometry>
        <sphere radius="0.007"/>
      </geometry>
    </collision>
    <collision>
      <origin rpy="0 0 0" xyz="0 0 0.025"/>
      <geometry>
        <sphere radius="0.007"/>
      </geometry>
    </collision>
  </link>
  <joint name="rh_RFJ2" type="revolute">
    <parent link="rh_rfproximal"/>
    <child link="rh_rfmiddle"/>
    <origin rpy="0 0 0" xyz="0 0 0.045"/>
    <axis xyz="1 0 0"/>
    <limit effort="2" lower="0" upper="1.57079632679" velocity="2.0"/>
    <dynamics damping="0.1"/>
  </joint>
  <link name="rh_rfdistal">
    <inertial>
      <origin xyz="0 0 0.012"/>
      <mass value="1"/>
      <inertia ixx="1" ixy="0.0" ixz="0.0" iyy="1" iyz="0.0" izz="1"/>
    </inertial>
    <visual>
      <origin rpy="0 0 0" xyz="0 0 0"/>
      <geometry name="rh_rfdistal_visual">
        <!-- Standard distal  -->
        <mesh filename="package://sr_description/hand/model/F1.dae" scale="0.001 0.001 0.001"/>
      </geometry>
      <material name="Grey"/>
    </visual>
    <collision>
      <origin rpy="0 0 0" xyz="0 0 0"/>
      <geometry name="rh_rfdistal_collision_geom">
        <!-- Standard distal  -->
        <mesh filename="package://sr_description/hand/model/F1.dae" scale="0.001 0.001 0.001"/>
      </geometry>
    </collision>
  </link>
  <joint name="rh_RFJ1" type="revolute">
    <parent link="rh_rfmiddle"/>
    <child link="rh_rfdistal"/>
    <origin rpy="0 0 0" xyz="0 0 0.025"/>
    <axis xyz="1 0 0"/>
    <!-- standard distal joint -->
    <limit effort="2" lower="0" upper="1.57079632679" velocity="2.0"/>
    <dynamics damping="0.1"/>
  </joint>

  <link name="rh_lfmetacarpal">
    <inertial>
      <origin rpy="0 0 0" xyz="0 0 0.04"/>
      <mass value="1"/>
      <inertia ixx="1" ixy="0.0" ixz="0.0" iyy="1" iyz="0.0" izz="1"/>
    </inertial>
    <visual>
      <origin rpy="0 0 0" xyz="0 0 0"/>
      <geometry name="rh_lfmetacarpal_visual">
        <mesh filename="package://sr_description/hand/model/lfmetacarpal.dae" scale="0.001 0.001 0.001"/>
      </geometry>
      <material name="Grey"/>
    </visual>
    <collision>
      <origin rpy="0 0 0" xyz="0 0 0.038"/>
      <geometry name="rh_lfmetacarpal_collision_geom">
        <box size="0.018 0.024 0.040"/>
      </geometry>
    </collision>
  </link>
  <joint name="rh_LFJ5" type="fixed">
    <parent link="rh_palm"/>
    <child link="rh_lfmetacarpal"/>
    <origin rpy="0 0 0" xyz="-0.033 0 0.02071"/>
    <!--<axis xyz="0.573576436 0 0.819152044"/>-->
    <!--<limit effort="2" lower="0" upper="0.785398163397" velocity="2.0"/>-->
    <!--<dynamics damping="0.1"/>-->
  </joint>
  <link name="rh_lfknuckle">
    <inertial>
      <origin rpy="0 0 0" xyz="0 0 0"/>
      <mass value="1"/>
      <inertia ixx="1" ixy="0.0" ixz="0.0" iyy="1" iyz="0.0" izz="1"/>
    </inertial>
    <visual>
      <origin rpy="0 0 0" xyz="0 0 0.0005"/>
      <geometry name="rh_lfknuckle_visual">
        <mesh filename="package://sr_description/hand/model/knuckle.dae" scale="0.001 0.001 0.001"/>
      </geometry>
      <material name="LightGrey"/>
    </visual>
    <collision>
      <origin rpy="0 1.5708 0" xyz="0 0 0"/>
      <geometry name="rh_lfknuckle_collision_geom">
        <cylinder length="0.014" radius="0.007"/>
      </geometry>
    </collision>
  </link>
  <joint name="rh_LFJ4" type="fixed">
    <parent link="rh_lfmetacarpal"/>
    <child link="rh_lfknuckle"/>
    <!--<origin xyz="0.033 0 0.095" rpy="0 0 0" />-->
    <origin rpy="0 0 0" xyz="0 0 0.06579"/>
    <!--<axis xyz="0 1.0 0"/>-->
    <!--<limit effort="2" lower="-0.349065850399" upper="0.349065850399" velocity="2.0"/>-->
    <!--<dynamics damping="0.1"/>-->
  </joint>
  <link name="rh_lfproximal">
    <inertial>
      <origin xyz="0 0 0.0225"/>
      <mass value="1"/>
      <inertia ixx="1" ixy="0.0" ixz="0.0" iyy="1" iyz="0.0" izz="1"/>
    </inertial>
    <visual>
      <origin rpy="0 0 0" xyz="0 0 0"/>
      <geometry name="rh_lfproximal_visual">
        <mesh filename="package://sr_description/hand/model/F3.dae" scale="0.001 0.001 0.001"/>
      </geometry>
      <material name="Grey"/>
    </visual>
    <collision>
      <origin rpy="0 0 0" xyz="0 0 0.025"/>
      <geometry name="rh_lfproximal_collision_geom">
        <cylinder length="0.040" radius="0.007"/>
      </geometry>
    </collision>
  </link>
  <joint name="rh_LFJ3" type="revolute">
    <parent link="rh_lfknuckle"/>
    <child link="rh_lfproximal"/>
    <origin rpy="0 0 0" xyz="0 0 0"/>
    <axis xyz="1 0 0"/>
    <limit effort="2" lower="0" upper="1.57079632679" velocity="2.0"/>
    <dynamics damping="0.1"/>
  </joint>
  <link name="rh_lfmiddle">
    <inertial>
      <origin rpy="0 0 0" xyz="0 0 0.0125"/>
      <mass value="1"/>
      <inertia ixx="1" ixy="0.0" ixz="0.0" iyy="1" iyz="0.0" izz="1"/>
    </inertial>
    <visual>
      <origin rpy="0 0 0" xyz="0 0 0"/>
      <geometry name="rh_lfmiddle_visual">
        <mesh filename="package://sr_description/hand/model/F2.dae" scale="0.001 0.001 0.001"/>
      </geometry>
      <material name="Grey"/>
    </visual>
    <collision>
      <origin rpy="0 0 0" xyz="0 0 0.0125"/>
      <geometry name="rh_lfmiddle_collision_geom">
        <cylinder length="0.025" radius="0.007"/>
      </geometry>
    </collision>
    <collision>
      <origin rpy="0 0 0" xyz="0 0 0.0"/>
      <geometry>
        <sphere radius="0.007"/>
      </geometry>
    </collision>
    <collision>
      <origin rpy="0 0 0" xyz="0 0 0.025"/>
      <geometry>
        <sphere radius="0.007"/>
      </geometry>
    </collision>
  </link>
  <joint name="rh_LFJ2" type="revolute">
    <parent link="rh_lfproximal"/>
    <child link="rh_lfmiddle"/>
    <origin rpy="0 0 0" xyz="0 0 0.045"/>
    <axis xyz="1 0 0"/>
    <limit effort="2" lower="0" upper="1.57079632679" velocity="2.0"/>
    <dynamics damping="0.1"/>
  </joint>
  <link name="rh_lfdistal">
    <inertial>
      <origin xyz="0 0 0.012"/>
      <mass value="1"/>
      <inertia ixx="1" ixy="0.0" ixz="0.0" iyy="1" iyz="0.0" izz="1"/>
    </inertial>
    <visual>
      <origin rpy="0 0 0" xyz="0 0 0"/>
      <geometry name="rh_lfdistal_visual">
        <!-- Standard distal  -->
        <mesh filename="package://sr_description/hand/model/F1.dae" scale="0.001 0.001 0.001"/>
      </geometry>
      <material name="Grey"/>
    </visual>
    <collision>
      <origin rpy="0 0 0" xyz="0 0 0"/>
      <geometry name="rh_lfdistal_collision_geom">
        <!-- Standard distal  -->
        <mesh filename="package://sr_description/hand/model/F1.dae" scale="0.001 0.001 0.001"/>
      </geometry>
    </collision>
  </link>
  <joint name="rh_LFJ1" type="revolute">
    <parent link="rh_lfmiddle"/>
    <child link="rh_lfdistal"/>
    <origin rpy="0 0 0" xyz="0 0 0.025"/>
    <axis xyz="1 0 0"/>
    <!-- standard distal joint -->
    <limit effort="2" lower="0" upper="1.57079632679" velocity="2.0"/>
    <dynamics damping="0.1"/>
  </joint>

  <link name="rh_thbase">
    <inertial>
      <origin rpy="0 0 0" xyz="0 0 0"/>
      <mass value="1"/>
      <inertia ixx="1" ixy="0.0" ixz="0.0" iyy="1" iyz="0.0" izz="1"/>
    </inertial>
    <visual>
      <origin rpy="0 0 0" xyz="0 0 0"/>
      <geometry name="rh_thbase_visual">
        <box size="0.001 0.001 0.001"/>
      </geometry>
      <material name="shadow_thbase_material">
        <color rgba="0.5 0.5 0.5 1.0"/>
      </material>
    </visual>
    <collision>
      <origin rpy="0 0 0" xyz="0 0 0"/>
      <geometry name="rh_thbase_collision_geom">
        <sphere radius="0.011"/>
      </geometry>
    </collision>
  </link>
  <joint name="rh_THJ5" type="revolute">
    <parent link="rh_palm"/>
    <child link="rh_thbase"/>
    <origin rpy="0 0.785398163397 0.0" xyz="0.034 -0.0085 0.029"/>
    <axis xyz="0 0 -1.0"/>
    <limit effort="5.0" lower="-1.0471975512" upper="1.0471975512" velocity="4.0"/>
    <dynamics damping="0.2"/>
  </joint>
  <link name="rh_thproximal">
    <inertial>
      <origin rpy="0 0 0" xyz="0 0 0.019"/>
      <mass value="1"/>
      <inertia ixx="1" ixy="0.0" ixz="0.0" iyy="1" iyz="0.0" izz="1"/>
    </inertial>
    <visual>
      <origin rpy="0 0 0" xyz="0 0 0"/>
      <geometry name="rh_thproximal_visual">
        <mesh filename="package://sr_description/hand/model/TH3_z.dae" scale="0.001 0.001 0.001"/>
      </geometry>
      <material name="shadow_thproximal_material">
        <color rgba="0.2 0.2 0.2 1.0"/>
      </material>
    </visual>
    <collision>
      <origin rpy="0 0 0" xyz="0 0 0.020"/>
      <geometry name="rh_thproximal_collision_geom">
        <cylinder length="0.018" radius="0.012"/>
      </geometry>
    </collision>
  </link>
  <joint name="rh_THJ4" type="revolute">
    <parent link="rh_thbase"/>
    <child link="rh_thproximal"/>
    <origin rpy="0 0 0" xyz="0 0 0"/>
    <axis xyz="1.0 0 0"/>
    <limit effort="3" lower="0.0" upper="1.2217304764" velocity="4.0"/>
    <dynamics damping="0.2"/>
  </joint>
  <link name="rh_thhub">
    <inertial>
      <origin rpy="0 0 0" xyz="0 0 0"/>
      <mass value="1"/>
      <inertia ixx="1" ixy="0.0" ixz="0.0" iyy="1" iyz="0.0" izz="1"/>
    </inertial>
    <visual>
      <origin rpy="0 0 0" xyz="0 0 0"/>
      <geometry name="rh_thhub_visual">
        <box size="0.001 0.001 0.001"/>
      </geometry>
      <material name="shadow_thhub_material">
        <color rgba="0.7 0.7 0.7 1.0"/>
      </material>
    </visual>
    <collision>
      <origin rpy="0 0 0" xyz="0 0 0"/>
      <geometry name="rh_thhub_collision_geom">
        <sphere radius="0.010"/>
      </geometry>
    </collision>
  </link>
  <joint name="rh_THJ3" type="revolute">
    <parent link="rh_thproximal"/>
    <child link="rh_thhub"/>
    <origin rpy="0 0 0" xyz="0 0 0.038"/>
    <axis xyz="1 0 0"/>
    <limit effort="2.0" lower="-0.209439510239" upper="0.209439510239" velocity="4.0"/>
    <dynamics damping="0.2"/>
  </joint>
  <link name="rh_thmiddle">
    <inertial>
      <origin rpy="0 0 0" xyz="0 0 0.016"/>
      <mass value="1"/>
      <inertia ixx="1" ixy="0.0" ixz="0.0" iyy="1" iyz="0.0" izz="1"/>
    </inertial>
    <visual>
      <origin rpy="0 0 0" xyz="0 0 0"/>
      <geometry name="rh_thmiddle_visual">
        <mesh filename="package://sr_description/hand/model/TH2_z.dae" scale="0.001 0.001 0.001"/>
      </geometry>
      <material name="shadow_thmiddle_material">
        <color rgba="0.2 0.2 0.2 1.0"/>
      </material>
    </visual>
    <collision>
      <origin rpy="0 0 0" xyz="0 0 0.012"/>
      <geometry name="rh_thmiddle_collision_geom">
        <cylinder length="0.018" radius="0.011"/>
      </geometry>
    </collision>
    <collision>
      <origin rpy="0 0 0" xyz="0 0 0.019"/>
      <geometry>
        <sphere radius="0.011"/>
      </geometry>
    </collision>
  </link>
  <joint name="rh_THJ2" type="revolute">
    <parent link="rh_thhub"/>
    <child link="rh_thmiddle"/>
    <origin rpy="0 0 0" xyz="0 0 0"/>
    <axis xyz="0 -1 0"/>
    <limit effort="2.0" lower="-0.698131700798" upper="0.698131700798" velocity="2.0"/>
    <dynamics damping="0.1"/>
  </joint>
  <link name="rh_thdistal">
    <inertial>
      <origin rpy="0 0 0" xyz="0 0 0.01375"/>
      <mass value="1"/>
      <inertia ixx="1" ixy="0.0" ixz="0.0" iyy="1" iyz="0.0" izz="1"/>
    </inertial>
    <visual>
      <origin rpy="0 0 0" xyz="0 0 0"/>
      <geometry name="rh_thdistal_visual">
        <!-- Standard distal  -->
        <mesh filename="package://sr_description/hand/model/TH1_z.dae" scale="0.001 0.001 0.001"/>
      </geometry>
      <material name="shadow_thmiddle_material">
        <color rgba="0.2 0.2 0.2 1.0"/>
      </material>
    </visual>
    <collision>
      <origin rpy="0 0 0" xyz="0 0 0"/>
      <geometry name="rh_thmiddle_collision_geom">
        <!-- Standard distal  -->
        <mesh filename="package://sr_description/hand/model/TH1_z.dae" scale="0.001 0.001 0.001"/>
        <!--      <box size="0.015 0.015 0.015" /> -->
      </geometry>
    </collision>
  </link>
  <joint name="rh_THJ1" type="revolute">
    <parent link="rh_thmiddle"/>
    <child link="rh_thdistal"/>
    <origin rpy="0 0 -1.57079632679" xyz="0 0 0.032"/>
    <axis xyz="1 0 0"/>
    <limit effort="1.0" lower="0" upper="1.57079632679" velocity="4.0"/>
    <dynamics damping="0.2"/>
  </joint>
</robot>