<?xml version="1.0" ?>
<!-- =================================================================================== -->
<!-- |    This document was autogenerated by xacro from inmoov_rightarm.urdf.xacro     | -->
<!-- |    EDITING THIS FILE BY HAND IS NOT RECOMMENDED                                 | -->
<!-- =================================================================================== -->
<robot name="inmoov" xmlns:xacro="http://ros.org/wiki/xacro">
  <!--xacro:property name="pi" value="3.1415926539"/-->
  <!-- meshlab steps taken from http://gazebosim.org/tutorials?tut=inertia -->
  <!-- assume material density is 1.0g per 1.0cm^2 -->
  <!-- ABS is 1.04g per 1.0cm^3 -->
  <!-- PLA is 1.25g per 1.0cm^3 -->
  <link name="world"/>
  <joint name="fixed" type="fixed">
    <parent link="world"/>
    <child link="r_shoulder_base_link"/>
  </joint>
  <link name="r_shoulder_base_link">
    <visual>
      <geometry>
        <mesh filename="package://inmoov_meshes/meshes/r_shoulder_base.stl" scale="0.001 0.001 0.001"/>
      </geometry>
      <origin rpy="0 0 0" xyz="0 0 0"/>
      <material name="cframe">
        <color rgba="0.40 0.40 0.40 1"/>
      </material>
    </visual>
    <inertial>
      <mass value="266.52696875"/>
      <inertia ixx="0.350410112" ixy="-0.0057351625" ixz="-0.011193818" iyy="0.3908856" iyz="0.045447476" izz="0.271458688"/>
    </inertial>
  </link>
  <link name="r_shoulder_link">
    <visual>
      <geometry>
        <mesh filename="package://inmoov_meshes/meshes/r_shoulder.stl" scale="0.001 0.001 0.001"/>
      </geometry>
      <origin rpy="0 0 0" xyz="0 0 0"/>
      <material name="cframe">
        <color rgba="0.40 0.40 0.40 1"/>
      </material>
    </visual>
    <inertial>
      <mass value="322.44334375"/>
      <inertia ixx="0.60134592" ixy="0.00343772975" ixz="-0.011761917" iyy="0.473865856" iyz="-0.114277" izz="0.500951584"/>
    </inertial>
  </link>
  <link name="r_bicep_link">
    <visual>
      <geometry>
        <mesh filename="package://inmoov_meshes/meshes/bicep.stl" scale="0.001 0.001 0.001"/>
      </geometry>
      <origin rpy="0 0 0" xyz="0 0 0"/>
      <material name="cframe">
        <color rgba="0.40 0.40 0.40 1"/>
      </material>
    </visual>
    <inertial>
      <mass value="281.91265625"/>
      <inertia ixx="1.283355392" ixy="-0.000200782203125" ixz="-0.224559104" iyy="1.399255168" iyz="0.0006545236875" izz="0.416621216"/>
    </inertial>
  </link>
  <link name="r_bicepcover_link">
    <visual>
      <geometry>
        <mesh filename="package://inmoov_meshes/meshes/bicepcover.stl" scale="0.001 0.001 0.001"/>
      </geometry>
      <origin rpy="0 0 0" xyz="0 0 0"/>
      <material name="ccover">
        <color rgba="0.75 0.75 0.75 1.0"/>
      </material>
    </visual>
    <inertial>
      <mass value="176.269609375"/>
      <inertia ixx="0.536349632" ixy="0.0009665334375" ixz="-0.069306768" iyy="0.625805568" iyz="0.0005666358125" izz="0.44191648"/>
    </inertial>
  </link>
  <link name="r_forearm_link">
    <visual>
      <geometry>
        <mesh filename="package://inmoov_meshes/meshes/r_forearm.stl" scale="0.001 0.001 0.001"/>
      </geometry>
      <origin rpy="0 0 0" xyz="0.001 0 0"/>
      <material name="ccover">
        <color rgba="0.75 0.75 0.75 1.0"/>
      </material>
    </visual>
    <inertial>
      <mass value="401.76659375"/>
      <inertia ixx="3.242307584" ixy="0.050011216" ixz="-0.14318512" iyy="3.24251008" iyz="0.086288976" izz="0.58458784"/>
    </inertial>
  </link>
  <joint name="r_shoulder_lift_joint" type="revolute">
    <axis xyz="0 1 0"/>
    <limit effort="1000.0" lower="-3.14159265359" upper="3.14159265359" velocity="1745.32925199"/>
    <origin rpy="0 0 0" xyz="0 -0.012 -0.04"/>
    <parent link="r_shoulder_base_link"/>
    <child link="r_shoulder_link"/>
  </joint>
  <joint name="r_upper_arm_roll_joint" type="revolute">
    <axis xyz="0 0 1"/>
    <limit effort="1000.0" lower="-3.14159265359" upper="3.14159265359" velocity="1745.32925199"/>
    <origin rpy="0 0 0" xyz="0 -0.066 -0.060"/>
    <parent link="r_shoulder_link"/>
    <child link="r_bicep_link"/>
  </joint>
  <joint name="r_elbow_flex_joint" type="revolute">
    <axis xyz="0 1 0"/>
    <limit effort="1000.0" lower="-3.14159265359" upper="3.14159265359" velocity="1745.32925199"/>
    <origin rpy="0 0 0" xyz="-0.0278 0 -0.2235"/>
    <parent link="r_bicep_link"/>
    <child link="r_forearm_link"/>
  </joint>
  <joint name="r_bicepcover_joint" type="fixed">
    <origin rpy="0 0 0" xyz="0 0 0"/>
    <parent link="r_bicep_link"/>
    <child link="r_bicepcover_link"/>
  </joint>
  <link name="r_hand_link">
    <visual>
      <geometry>
        <cylinder length="0.11" radius="0.06"/>
      </geometry>
      <origin rpy="0 0 0" xyz="0 0 0.055"/>
      <material name="cbase">
        <color rgba="0.1 0.1 0.1 1"/>
      </material>
    </visual>
  </link>
  <joint name="r_wrist_roll_joint" type="revolute">
    <axis xyz="0 0 1"/>
    <limit effort="1000.0" lower="-3.14159265359" upper="3.14159265359" velocity="1745.32925199"/>
    <origin rpy="0 0 0" xyz="-0.0144 0.01  -0.2885"/>
    <parent link="r_forearm_link"/>
    <child link="r_hand_link"/>
  </joint>
</robot>

