<?xml version="1.0" ?>
<!-- =================================================================================== -->
<!-- |    This document was autogenerated by xacro from inmoov_right_hand.urdf.xacro   | -->
<!-- |    EDITING THIS FILE BY HAND IS NOT RECOMMENDED                                 | -->
<!-- =================================================================================== -->
<robot name="inmoov_hand" xmlns:xacro="http://ros.org/wiki/xacro">
  <!--xacro:property name="pi" value="3.1415926539"/-->
  <!-- meshlab steps taken from http://gazebosim.org/tutorials?tut=inertia -->
  <!-- assume material density is 1.0g per 1.0cm^2 -->
  <!-- ABS is 1.04g per 1.0cm^3 -->
  <!-- PLA is 1.25g per 1.0cm^3 -->
  <link name="base_link">
    <visual>
      <geometry>
        <cylinder length="0.0001" radius="0.26"/>
      </geometry>
      <origin rpy="0 0 0" xyz="0 0 0.055"/>
      <material name="invisible">
        <color rgba="0.3 0.3 0.3 0"/>
      </material>
    </visual>
  </link>
  <link name="r_hand_link">
    <visual>
      <geometry>
        <mesh filename="package://inmoov_meshes/meshes/r_hand.stl" scale="0.001 0.001 0.001"/>
      </geometry>
      <origin rpy="0 0 0" xyz="0 0 0"/>
      <material name="cframe">
        <color rgba="0.40 0.40 0.40 1"/>
      </material>
    </visual>
    <collision>
      <geometry>
        <mesh filename="package://inmoov_meshes/meshes/r_hand.stl" scale="0.001 0.001 0.001"/>
      </geometry>
      <origin rpy="0 0 0" xyz="0 0 0"/>
    </collision>
    <inertial>
      <mass value="83.605"/>
      <inertia ixx="0.126485184" ixy="6.837660156e-06" ixz="-0.000139862265625" iyy="0.094925672" iyz="0.023795198" izz="0.037456164"/>
    </inertial>
  </link>
  <link name="r_thumb1_link">
    <visual>
      <geometry>
        <mesh filename="package://inmoov_meshes/meshes/r_thumb5_1.stl" scale="0.001 0.001 0.001"/>
      </geometry>
      <origin rpy="0 0 0" xyz="0 0 0"/>
      <material name="cframe">
        <color rgba="0.40 0.40 0.40 1"/>
      </material>
    </visual>
    <collision>
      <geometry>
        <mesh filename="package://inmoov_meshes/meshes/r_thumb5_1.stl" scale="0.001 0.001 0.001"/>
      </geometry>
      <origin rpy="0 0 0" xyz="0 0 0"/>
    </collision>
    <inertial>
      <mass value="10.044436523"/>
      <inertia ixx="0.001744373375" ixy="-4.0159230469e-05" ixz="4.101596875e-05" iyy="0.001225091875" iyz="0.00024317490625" izz="0.0011855675"/>
    </inertial>
  </link>
  <link name="r_thumb2_link">
    <visual>
      <geometry>
        <mesh filename="package://inmoov_meshes/meshes/thumb5_2.stl" scale="0.001 0.001 0.001"/>
      </geometry>
      <origin rpy="0 0 0" xyz="0 0 0"/>
      <material name="cframe">
        <color rgba="0.40 0.40 0.40 1"/>
      </material>
    </visual>
    <collision>
      <geometry>
        <mesh filename="package://inmoov_meshes/meshes/thumb5_2.stl" scale="0.001 0.001 0.001"/>
      </geometry>
      <origin rpy="0 0 0" xyz="0 0 0"/>
    </collision>
    <inertial>
      <mass value="7.511052246"/>
      <inertia ixx="0.0013042445" ixy="2.49766266e-07" ixz="4.229196289e-06" iyy="0.001169623125" iyz="9.06593506e-07" izz="0.000555691125"/>
    </inertial>
  </link>
  <link name="r_thumb3_link">
    <visual>
      <geometry>
        <mesh filename="package://inmoov_meshes/meshes/thumb5_3.stl" scale="0.001 0.001 0.001"/>
      </geometry>
      <origin rpy="0 0 0" xyz="0 0 0"/>
      <material name="cframe">
        <color rgba="0.40 0.40 0.40 1"/>
      </material>
    </visual>
    <collision>
      <geometry>
        <mesh filename="package://inmoov_meshes/meshes/thumb5_3.stl" scale="0.001 0.001 0.001"/>
      </geometry>
      <origin rpy="0 0 0" xyz="0 0 0"/>
    </collision>
    <inertial>
      <mass value="5.81254541"/>
      <inertia ixx="0.0007149901875" ixy="-4.4194165e-07" ixz="-5.5290855469e-05" iyy="0.00073545675" iyz="4.97618683e-07" izz="0.00026050759375"/>
    </inertial>
  </link>
  <link name="r_index1_link">
    <visual>
      <geometry>
        <mesh filename="package://inmoov_meshes/meshes/index3_1.stl" scale="0.001 0.001 0.001"/>
      </geometry>
      <origin rpy="0 0 0" xyz="0 0 0"/>
      <material name="cframe">
        <color rgba="0.40 0.40 0.40 1"/>
      </material>
    </visual>
    <collision>
      <geometry>
        <mesh filename="package://inmoov_meshes/meshes/index3_1.stl" scale="0.001 0.001 0.001"/>
      </geometry>
      <origin rpy="0 0 0" xyz="0 0 0"/>
    </collision>
    <inertial>
      <mass value="4.854550781"/>
      <inertia ixx="0.0007855188125" ixy="-1.13786087e-07" ixz="1.2465399414e-05" iyy="0.0007367950625" iyz="1.496518921e-06" izz="0.000226730125"/>
    </inertial>
  </link>
  <link name="r_index2_link">
    <visual>
      <geometry>
        <mesh filename="package://inmoov_meshes/meshes/index3_2.stl" scale="0.001 0.001 0.001"/>
      </geometry>
      <origin rpy="0 0 0" xyz="0 0 0"/>
      <material name="cframe">
        <color rgba="0.40 0.40 0.40 1"/>
      </material>
    </visual>
    <collision>
      <geometry>
        <mesh filename="package://inmoov_meshes/meshes/index3_2.stl" scale="0.001 0.001 0.001"/>
      </geometry>
      <origin rpy="0 0 0" xyz="0 0 0"/>
    </collision>
    <inertial>
      <mass value="2.911548828"/>
      <inertia ixx="0.0002476975625" ixy="5.310544e-09" ixz="-1.3615135742e-05" iyy="0.0002445083125" iyz="7.01601379e-07" izz="9.1051476562e-05"/>
    </inertial>
  </link>
  <link name="r_index3_link">
    <visual>
      <geometry>
        <mesh filename="package://inmoov_meshes/meshes/index3_3.stl" scale="0.001 0.001 0.001"/>
      </geometry>
      <origin rpy="0 0 0" xyz="0 0 0"/>
      <material name="cframe">
        <color rgba="0.40 0.40 0.40 1"/>
      </material>
    </visual>
    <collision>
      <geometry>
        <mesh filename="package://inmoov_meshes/meshes/index3_3.stl" scale="0.001 0.001 0.001"/>
      </geometry>
      <origin rpy="0 0 0" xyz="0 0 0"/>
    </collision>
    <inertial>
      <mass value="2.754759033"/>
      <inertia ixx="0.000240287703125" ixy="2.6071491e-08" ixz="-1.3973435547e-05" iyy="0.000244506625" iyz="8.4088615e-08" izz="7.2536453125e-05"/>
    </inertial>
  </link>
  <link name="r_middle1_link">
    <visual>
      <geometry>
        <mesh filename="package://inmoov_meshes/meshes/middle3_1.stl" scale="0.001 0.001 0.001"/>
      </geometry>
      <origin rpy="0 0 0" xyz="0 0 0"/>
      <material name="cframe">
        <color rgba="0.40 0.40 0.40 1"/>
      </material>
    </visual>
    <collision>
      <geometry>
        <mesh filename="package://inmoov_meshes/meshes/middle3_1.stl" scale="0.001 0.001 0.001"/>
      </geometry>
      <origin rpy="0 0 0" xyz="0 0 0"/>
    </collision>
    <inertial>
      <mass value="5.988140625"/>
      <inertia ixx="0.00111485875" ixy="-2.6224279e-08" ixz="1.7385302734e-05" iyy="0.00104555775" iyz="1.371758545e-06" izz="0.0003216090625"/>
    </inertial>
  </link>
  <link name="r_middle2_link">
    <visual>
      <geometry>
        <mesh filename="package://inmoov_meshes/meshes/middle3_2.stl" scale="0.001 0.001 0.001"/>
      </geometry>
      <origin rpy="0 0 0" xyz="0 0 0"/>
      <material name="cframe">
        <color rgba="0.40 0.40 0.40 1"/>
      </material>
    </visual>
    <collision>
      <geometry>
        <mesh filename="package://inmoov_meshes/meshes/middle3_2.stl" scale="0.001 0.001 0.001"/>
      </geometry>
      <origin rpy="0 0 0" xyz="0 0 0"/>
    </collision>
    <inertial>
      <mass value="3.588543701"/>
      <inertia ixx="0.00035095146875" ixy="1.9666632e-08" ixz="-1.9434296875e-05" iyy="0.000346446375" iyz="1.214759033e-06" izz="0.000129022828125"/>
    </inertial>
  </link>
  <link name="r_middle3_link">
    <visual>
      <geometry>
        <mesh filename="package://inmoov_meshes/meshes/middle3_3.stl" scale="0.001 0.001 0.001"/>
      </geometry>
      <origin rpy="0 0 0" xyz="0 0 0"/>
      <material name="cframe">
        <color rgba="0.40 0.40 0.40 1"/>
      </material>
    </visual>
    <collision>
      <geometry>
        <mesh filename="package://inmoov_meshes/meshes/middle3_3.stl" scale="0.001 0.001 0.001"/>
      </geometry>
      <origin rpy="0 0 0" xyz="0 0 0"/>
    </collision>
    <inertial>
      <mass value="3.395293457"/>
      <inertia ixx="0.00034045084375" ixy="3.217115e-08" ixz="-1.9707763672e-05" iyy="0.00034641909375" iyz="2.6280695e-08" izz="0.00010276375"/>
    </inertial>
  </link>
  <link name="r_ring1_link">
    <visual>
      <geometry>
        <mesh filename="package://inmoov_meshes/meshes/r_ring3_1.stl" scale="0.001 0.001 0.001"/>
      </geometry>
      <origin rpy="0 0 0" xyz="0 0 0"/>
      <material name="cframe">
        <color rgba="0.40 0.40 0.40 1"/>
      </material>
    </visual>
    <collision>
      <geometry>
        <mesh filename="package://inmoov_meshes/meshes/r_ring3_1.stl" scale="0.001 0.001 0.001"/>
      </geometry>
      <origin rpy="0 0 0" xyz="0 0 0"/>
    </collision>
    <inertial>
      <mass value="10.81030957"/>
      <inertia ixx="0.0023923495" ixy="2.5959337891e-05" ixz="1.8166240234e-05" iyy="0.001249956375" iyz="-0.000426506625" izz="0.001810718375"/>
    </inertial>
  </link>
  <link name="r_ring2_link">
    <visual>
      <geometry>
        <mesh filename="package://inmoov_meshes/meshes/ring3_2.stl" scale="0.001 0.001 0.001"/>
      </geometry>
      <origin rpy="0 0 0" xyz="0 0 0"/>
      <material name="cframe">
        <color rgba="0.40 0.40 0.40 1"/>
      </material>
    </visual>
    <collision>
      <geometry>
        <mesh filename="package://inmoov_meshes/meshes/ring3_2.stl" scale="0.001 0.001 0.001"/>
      </geometry>
      <origin rpy="0 0 0" xyz="0 0 0"/>
    </collision>
    <inertial>
      <mass value="4.222559082"/>
      <inertia ixx="0.0006227740625" ixy="5.753471e-09" ixz="1.0004874023e-05" iyy="0.0005840455625" iyz="7.29796631e-07" izz="0.000179666234375"/>
    </inertial>
  </link>
  <link name="r_ring3_link">
    <visual>
      <geometry>
        <mesh filename="package://inmoov_meshes/meshes/ring3_3.stl" scale="0.001 0.001 0.001"/>
      </geometry>
      <origin rpy="0 0 0" xyz="0 0 0"/>
      <material name="cframe">
        <color rgba="0.40 0.40 0.40 1"/>
      </material>
    </visual>
    <collision>
      <geometry>
        <mesh filename="package://inmoov_meshes/meshes/ring3_3.stl" scale="0.001 0.001 0.001"/>
      </geometry>
      <origin rpy="0 0 0" xyz="0 0 0"/>
    </collision>
    <inertial>
      <mass value="2.530003662"/>
      <inertia ixx="0.000195998" ixy="1.0986977e-08" ixz="-1.0853751953e-05" iyy="0.00019348203125" iyz="6.78437927e-07" izz="7.2056179688e-05"/>
    </inertial>
  </link>
  <link name="r_ring4_link">
    <visual>
      <geometry>
        <mesh filename="package://inmoov_meshes/meshes/ring3_4.stl" scale="0.001 0.001 0.001"/>
      </geometry>
      <origin rpy="0 0 0" xyz="0 0 0"/>
      <material name="cframe">
        <color rgba="0.40 0.40 0.40 1"/>
      </material>
    </visual>
    <collision>
      <geometry>
        <mesh filename="package://inmoov_meshes/meshes/ring3_4.stl" scale="0.001 0.001 0.001"/>
      </geometry>
      <origin rpy="0 0 0" xyz="0 0 0"/>
    </collision>
    <inertial>
      <mass value="2.393758301"/>
      <inertia ixx="0.000190133796875" ixy="1.7969458e-08" ixz="-1.1006313477e-05" iyy="0.0001934669375" iyz="1.4700538e-08" izz="5.7391125e-05"/>
    </inertial>
  </link>
  <link name="r_pinky1_link">
    <visual>
      <geometry>
        <mesh filename="package://inmoov_meshes/meshes/r_pinky3_1.stl" scale="0.001 0.001 0.001"/>
      </geometry>
      <origin rpy="0 0 0" xyz="0 0 0"/>
      <material name="cframe">
        <color rgba="0.40 0.40 0.40 1"/>
      </material>
    </visual>
    <collision>
      <geometry>
        <mesh filename="package://inmoov_meshes/meshes/r_pinky3_1.stl" scale="0.001 0.001 0.001"/>
      </geometry>
      <origin rpy="0 0 0" xyz="0 0 0"/>
    </collision>
    <inertial>
      <mass value="14.892949219"/>
      <inertia ixx="0.0043610115" ixy="3.6622980469e-05" ixz="2.9569984375e-05" iyy="0.00215359975" iyz="-0.001214404375" izz="0.003112752"/>
    </inertial>
  </link>
  <link name="r_pinky2_link">
    <visual>
      <geometry>
        <mesh filename="package://inmoov_meshes/meshes/pinky3_2.stl" scale="0.001 0.001 0.001"/>
      </geometry>
      <origin rpy="0 0 0" xyz="0 0 0"/>
      <material name="cframe">
        <color rgba="0.40 0.40 0.40 1"/>
      </material>
    </visual>
    <collision>
      <geometry>
        <mesh filename="package://inmoov_meshes/meshes/pinky3_2.stl" scale="0.001 0.001 0.001"/>
      </geometry>
      <origin rpy="0 0 0" xyz="0 0 0"/>
    </collision>
    <inertial>
      <mass value="3.053924072"/>
      <inertia ixx="0.00036256315625" ixy="-3.0389627e-08" ixz="5.979022461e-06" iyy="0.00033987203125" iyz="6.57904663e-07" izz="0.00010569428125"/>
    </inertial>
  </link>
  <link name="r_pinky3_link">
    <visual>
      <geometry>
        <mesh filename="package://inmoov_meshes/meshes/pinky3_3.stl" scale="0.001 0.001 0.001"/>
      </geometry>
      <origin rpy="0 0 0" xyz="0 0 0"/>
      <material name="cframe">
        <color rgba="0.40 0.40 0.40 1"/>
      </material>
    </visual>
    <collision>
      <geometry>
        <mesh filename="package://inmoov_meshes/meshes/pinky3_3.stl" scale="0.001 0.001 0.001"/>
      </geometry>
      <origin rpy="0 0 0" xyz="0 0 0"/>
    </collision>
    <inertial>
      <mass value="1.84870752"/>
      <inertia ixx="0.000116124148438" ixy="1.6077593e-08" ixz="-6.393164551e-06" iyy="0.000114666492188" iyz="3.92228394e-07" izz="4.2715207031e-05"/>
    </inertial>
  </link>
  <link name="r_pinky4_link">
    <visual>
      <geometry>
        <mesh filename="package://inmoov_meshes/meshes/pinky3_4.stl" scale="0.001 0.001 0.001"/>
      </geometry>
      <origin rpy="0 0 0" xyz="0 0 0"/>
      <material name="cframe">
        <color rgba="0.40 0.40 0.40 1"/>
      </material>
    </visual>
    <collision>
      <geometry>
        <mesh filename="package://inmoov_meshes/meshes/pinky3_4.stl" scale="0.001 0.001 0.001"/>
      </geometry>
      <origin rpy="0 0 0" xyz="0 0 0"/>
    </collision>
    <inertial>
      <mass value="1.748221436"/>
      <inertia ixx="0.000112612445312" ixy="1.0655196e-08" ixz="-6.518796875e-06" iyy="0.00011458659375" iyz="8.84516e-09" izz="3.3991617188e-05"/>
    </inertial>
  </link>
  <joint name="r_thumb1_joint" type="revolute">
    <axis xyz="0 0 1"/>
    <limit effort="1000.0" lower="-0.0872664625997" upper="1.1344640138" velocity="0.0"/>
    <origin rpy="0.1 0 0" xyz="0 0.029 -0.0577"/>
    <parent link="r_hand_link"/>
    <child link="r_thumb1_link"/>
  </joint>
  <joint name="r_thumb_joint" type="revolute">
    <axis xyz="0 1 0"/>
    <limit effort="1000.0" lower="-0.0872664625997" upper="1.1344640138" velocity="0.0"/>
    <origin rpy="0.825 -0.1 0.3" xyz="-0.00052 0.02725  -0.013"/>
    <parent link="r_thumb1_link"/>
    <child link="r_thumb2_link"/>
  </joint>
  <joint name="r_thumb3_joint" type="revolute">
    <axis xyz="0 1 0"/>
    <limit effort="1000.0" lower="-0.0872664625997" upper="1.1344640138" velocity="0.0"/>
    <origin rpy="0 0 0" xyz="0 0 -0.035"/>
    <parent link="r_thumb2_link"/>
    <child link="r_thumb3_link"/>
  </joint>
  <joint name="r_index1_joint" type="revolute">
    <axis xyz="0 1 0"/>
    <limit effort="1000.0" lower="-0.0872664625997" upper="1.4835298642" velocity="0.0"/>
    <origin rpy="0.1 0 0" xyz="-0.0015 0.0342  -0.119"/>
    <parent link="r_hand_link"/>
    <child link="r_index1_link"/>
  </joint>
  <joint name="r_index_joint" type="revolute">
    <axis xyz="0 1 0"/>
    <limit effort="1000.0" lower="-0.0872664625997" upper="1.4835298642" velocity="0.0"/>
    <origin rpy="0 0 0" xyz="0 0.001 -0.03595"/>
    <parent link="r_index1_link"/>
    <child link="r_index2_link"/>
  </joint>
  <joint name="r_index3_joint" type="revolute">
    <axis xyz="0 1 0"/>
    <limit effort="1000.0" lower="-0.0872664625997" upper="1.4835298642" velocity="0.0"/>
    <origin rpy="0 0 0" xyz="0 0 -0.024"/>
    <parent link="r_index2_link"/>
    <child link="r_index3_link"/>
  </joint>
  <joint name="r_middle1_joint" type="revolute">
    <axis xyz="0 1 0"/>
    <limit effort="1000.0" lower="-0.0872664625997" upper="1.4835298642" velocity="0.0"/>
    <origin rpy="0 0 0" xyz="-0.00175 0.007  -0.12325"/>
    <parent link="r_hand_link"/>
    <child link="r_middle1_link"/>
  </joint>
  <joint name="r_middle_joint" type="revolute">
    <axis xyz="0 1 0"/>
    <limit effort="1000.0" lower="-0.0872664625997" upper="1.4835298642" velocity="0.0"/>
    <origin rpy="0 0 0" xyz="0 0.000 -0.0389"/>
    <parent link="r_middle1_link"/>
    <child link="r_middle2_link"/>
  </joint>
  <joint name="r_middle3_joint" type="revolute">
    <axis xyz="0 1 0"/>
    <limit effort="1000.0" lower="-0.0872664625997" upper="1.4835298642" velocity="0.0"/>
    <origin rpy="0 0 0" xyz="0 0.0005 -0.0259"/>
    <parent link="r_middle2_link"/>
    <child link="r_middle3_link"/>
  </joint>
  <joint name="r_ring1_joint" type="revolute">
    <axis xyz="0 0 1"/>
    <limit effort="1000.0" lower="-0.0872664625997" upper="1.4835298642" velocity="0.0"/>
    <origin rpy="0.7 0 0" xyz="0 -0.00705 -0.0794"/>
    <parent link="r_hand_link"/>
    <child link="r_ring1_link"/>
  </joint>
  <joint name="r_ring_joint" type="revolute">
    <axis xyz="0 1 0"/>
    <limit effort="1000.0" lower="-0.0872664625997" upper="1.4835298642" velocity="0.0"/>
    <origin rpy="-0.7775 0 0" xyz="0.00126 -0.0351 -0.0166"/>
    <parent link="r_ring1_link"/>
    <child link="r_ring2_link"/>
  </joint>
  <joint name="r_ring3_joint" type="revolute">
    <axis xyz="0 1 0"/>
    <limit effort="1000.0" lower="-0.0872664625997" upper="1.4835298642" velocity="0.0"/>
    <origin rpy="0 0 0" xyz="0 0.0005 -0.0345"/>
    <parent link="r_ring2_link"/>
    <child link="r_ring3_link"/>
  </joint>
  <joint name="r_ring4_joint" type="revolute">
    <axis xyz="0 1 0"/>
    <limit effort="1000.0" lower="-0.0872664625997" upper="1.4835298642" velocity="0.0"/>
    <origin rpy="0 0 0" xyz="0 0.0004 -0.0229"/>
    <parent link="r_ring3_link"/>
    <child link="r_ring4_link"/>
  </joint>
  <joint name="r_pinky1_joint" type="revolute">
    <axis xyz="0 0 1"/>
    <limit effort="1000.0" lower="-0.0872664625997" upper="1.4835298642" velocity="0.0"/>
    <origin rpy="0.7 0 0" xyz="0 -0.027 -0.0555"/>
    <parent link="r_hand_link"/>
    <child link="r_pinky1_link"/>
  </joint>
  <joint name="r_pinky_joint" type="revolute">
    <axis xyz="0 1 0"/>
    <limit effort="1000.0" lower="-0.0872664625997" upper="1.4835298642" velocity="0.0"/>
    <origin rpy="-0.93 0 0" xyz="0 -0.046 -0.0228"/>
    <parent link="r_pinky1_link"/>
    <child link="r_pinky2_link"/>
  </joint>
  <joint name="r_pinky3_joint" type="revolute">
    <axis xyz="0 1 0"/>
    <limit effort="1000.0" lower="-0.0872664625997" upper="1.4835298642" velocity="0.0"/>
    <origin rpy="0 0 0" xyz="0 0.0005 -0.031"/>
    <parent link="r_pinky2_link"/>
    <child link="r_pinky3_link"/>
  </joint>
  <joint name="r_pinky4_joint" type="revolute">
    <axis xyz="0 1 0"/>
    <limit effort="1000.0" lower="-0.0872664625997" upper="1.4835298642" velocity="0.0"/>
    <origin rpy="0 0 0" xyz="0 0.0004 -0.0208"/>
    <parent link="r_pinky3_link"/>
    <child link="r_pinky4_link"/>
  </joint>
  <link name="r_handcover_link">
    <visual>
      <geometry>
        <mesh filename="package://inmoov_meshes/meshes/r_cover_hand.stl" scale="0.001 0.001 0.001"/>
      </geometry>
      <origin rpy="0 0 0" xyz="0 0 0"/>
      <material name="ccover">
        <color rgba="0.75 0.75 0.75 1.0"/>
      </material>
    </visual>
    <collision>
      <geometry>
        <mesh filename="package://inmoov_meshes/meshes/r_cover_hand.stl" scale="0.001 0.001 0.001"/>
      </geometry>
      <origin rpy="0 0 0" xyz="0 0 0"/>
    </collision>
    <inertial>
      <mass value="39.850042969"/>
      <inertia ixx="0.043945364" ixy="0.00015029871875" ixz="-0.0006684343125" iyy="0.03162573" iyz="0.0078745195" izz="0.01280806"/>
    </inertial>
  </link>
  <link name="r_cover_handring_link">
    <visual>
      <geometry>
        <mesh filename="package://inmoov_meshes/meshes/r_cover_handring.stl" scale="0.001 0.001 0.001"/>
      </geometry>
      <origin rpy="0 0 0" xyz="0 0 0"/>
      <material name="ccover">
        <color rgba="0.75 0.75 0.75 1.0"/>
      </material>
    </visual>
    <collision>
      <geometry>
        <mesh filename="package://inmoov_meshes/meshes/r_cover_handring.stl" scale="0.001 0.001 0.001"/>
      </geometry>
      <origin rpy="0 0 0" xyz="0 0 0"/>
    </collision>
    <inertial>
      <mass value="3.50753833"/>
      <inertia ixx="0.000430487" ixy="-5.051600586e-06" ixz="-2.255701172e-06" iyy="0.00028864628125" iyz="-5.9473761e-07" izz="0.00015917009375"/>
    </inertial>
  </link>
  <link name="r_cover_handpinky_link">
    <visual>
      <geometry>
        <mesh filename="package://inmoov_meshes/meshes/r_cover_handpinky.stl" scale="0.001 0.001 0.001"/>
      </geometry>
      <origin rpy="0 0 0" xyz="0 0 0"/>
      <material name="ccover">
        <color rgba="0.75 0.75 0.75 1.0"/>
      </material>
    </visual>
    <collision>
      <geometry>
        <mesh filename="package://inmoov_meshes/meshes/r_cover_handpinky.stl" scale="0.001 0.001 0.001"/>
      </geometry>
      <origin rpy="0 0 0" xyz="0 0 0"/>
    </collision>
    <inertial>
      <mass value="3.887731445"/>
      <inertia ixx="0.0007326291875" ixy="-2.534063232e-06" ixz="2.594331299e-06" iyy="0.00057801175" iyz="-6.7645304688e-05" izz="0.0001684065625"/>
    </inertial>
  </link>
  <link name="r_cover_thumb_link">
    <visual>
      <geometry>
        <mesh filename="package://inmoov_meshes/meshes/r_cover_thumb.stl" scale="0.001 0.001 0.001"/>
      </geometry>
      <origin rpy="0 0 0" xyz="0 0 0"/>
      <material name="ccover">
        <color rgba="0.75 0.75 0.75 1.0"/>
      </material>
    </visual>
    <collision>
      <geometry>
        <mesh filename="package://inmoov_meshes/meshes/r_cover_thumb.stl" scale="0.001 0.001 0.001"/>
      </geometry>
      <origin rpy="0 0 0" xyz="0 0 0"/>
    </collision>
    <inertial>
      <mass value="3.250209961"/>
      <inertia ixx="0.0005435319375" ixy="-4.525456055e-06" ixz="8.495842773e-06" iyy="0.00044260215625" iyz="4.9077523438e-05" izz="0.000112376625"/>
    </inertial>
  </link>
  <link name="r_cover_index_link">
    <visual>
      <geometry>
        <mesh filename="package://inmoov_meshes/meshes/r_cover_index.stl" scale="0.001 0.001 0.001"/>
      </geometry>
      <origin rpy="0 0 0" xyz="0 0 0"/>
      <material name="ccover">
        <color rgba="0.75 0.75 0.75 1.0"/>
      </material>
    </visual>
    <collision>
      <geometry>
        <mesh filename="package://inmoov_meshes/meshes/r_cover_index.stl" scale="0.001 0.001 0.001"/>
      </geometry>
      <origin rpy="0 0 0" xyz="0 0 0"/>
    </collision>
    <inertial>
      <mass value="1.635368652"/>
      <inertia ixx="0.000167985140625" ixy="-9.36647e-10" ixz="-1.5635599609e-05" iyy="0.0001404111875" iyz="-6.99011047e-07" izz="3.6513273438e-05"/>
    </inertial>
  </link>
  <link name="r_cover_middle_link">
    <visual>
      <geometry>
        <mesh filename="package://inmoov_meshes/meshes/r_cover_middle.stl" scale="0.001 0.001 0.001"/>
      </geometry>
      <origin rpy="0 0 0" xyz="0 0 0"/>
      <material name="ccover">
        <color rgba="0.75 0.75 0.75 1.0"/>
      </material>
    </visual>
    <collision>
      <geometry>
        <mesh filename="package://inmoov_meshes/meshes/r_cover_middle.stl" scale="0.001 0.001 0.001"/>
      </geometry>
      <origin rpy="0 0 0" xyz="0 0 0"/>
    </collision>
    <inertial>
      <mass value="1.904471313"/>
      <inertia ixx="0.000234427671875" ixy="-1.1994104e-08" ixz="-2.2417498047e-05" iyy="0.000198775875" iyz="-9.45323303e-07" izz="4.7098675781e-05"/>
    </inertial>
  </link>
  <link name="r_cover_ring_link">
    <visual>
      <geometry>
        <mesh filename="package://inmoov_meshes/meshes/r_cover_ring.stl" scale="0.001 0.001 0.001"/>
      </geometry>
      <origin rpy="0 0 0" xyz="0 0 0"/>
      <material name="ccover">
        <color rgba="0.75 0.75 0.75 1.0"/>
      </material>
    </visual>
    <collision>
      <geometry>
        <mesh filename="package://inmoov_meshes/meshes/r_cover_ring.stl" scale="0.001 0.001 0.001"/>
      </geometry>
      <origin rpy="0 0 0" xyz="0 0 0"/>
    </collision>
    <inertial>
      <mass value="1.466901733"/>
      <inertia ixx="0.0001476946875" ixy="-1.216691284e-06" ixz="-1.2881797852e-05" iyy="0.000124547375" iyz="-4.381839844e-06" izz="3.0177607422e-05"/>
    </inertial>
  </link>
  <link name="r_cover_pinky_link">
    <visual>
      <geometry>
        <mesh filename="package://inmoov_meshes/meshes/r_cover_pinky.stl" scale="0.001 0.001 0.001"/>
      </geometry>
      <origin rpy="0 0 0" xyz="0 0 0"/>
      <material name="ccover">
        <color rgba="0.75 0.75 0.75 1.0"/>
      </material>
    </visual>
    <collision>
      <geometry>
        <mesh filename="package://inmoov_meshes/meshes/r_cover_pinky.stl" scale="0.001 0.001 0.001"/>
      </geometry>
      <origin rpy="0 0 0" xyz="0 0 0"/>
    </collision>
    <inertial>
      <mass value="1.2856073"/>
      <inertia ixx="0.000109421882812" ixy="-9.04252136e-07" ixz="-9.149e-06" iyy="9.0519320312e-05" iyz="-2.714452637e-06" izz="2.4557162109e-05"/>
    </inertial>
  </link>
  <joint name="r_handcover_joint" type="fixed">
    <origin rpy="0 0 0" xyz="0.009 0.0192 -0.0977"/>
    <parent link="r_hand_link"/>
    <child link="r_handcover_link"/>
  </joint>
  <joint name="r_cover_handpinky_joint" type="fixed">
    <origin rpy="-0.7 0 0" xyz="0.01 -0.02025 -0.0071"/>
    <parent link="r_pinky1_link"/>
    <child link="r_cover_handpinky_link"/>
  </joint>
  <joint name="r_cover_handring_joint" type="fixed">
    <origin rpy="-0.7 0 0" xyz="0.009 -0.015 -0.0008"/>
    <parent link="r_ring1_link"/>
    <child link="r_cover_handring_link"/>
  </joint>
  <joint name="r_cover_middle_joint" type="fixed">
    <origin rpy="0 -0.05 0" xyz="0.0071 0 -0.012"/>
    <parent link="r_middle1_link"/>
    <child link="r_cover_middle_link"/>
  </joint>
  <joint name="r_cover_thumb_joint" type="fixed">
    <origin rpy="0.05 0 0" xyz="0.01 0.02125 0.0047"/>
    <parent link="r_thumb1_link"/>
    <child link="r_cover_thumb_link"/>
  </joint>
  <joint name="r_cover_index_joint" type="fixed">
    <origin rpy="0 0.05 0" xyz="0.0071 0 -0.012"/>
    <parent link="r_index1_link"/>
    <child link="r_cover_index_link"/>
  </joint>
  <joint name="r_cover_ring_joint" type="fixed">
    <origin rpy="0.1 -0.05 0" xyz="0.005 0 -0.011"/>
    <parent link="r_ring2_link"/>
    <child link="r_cover_ring_link"/>
  </joint>
  <joint name="r_cover_pinky_joint" type="fixed">
    <origin rpy="0.1 -0.05 0" xyz="0.005 0 -0.0105"/>
    <parent link="r_pinky2_link"/>
    <child link="r_cover_pinky_link"/>
  </joint>
  <joint name="base_to_hand_joint" type="revolute">
    <axis xyz="0 0 1"/>
    <limit effort="1000.0" lower="-3.14" upper="0" velocity="0.5"/>
    <origin rpy="0 0 0" xyz="0 0 0"/>
    <parent link="base_link"/>
    <child link="r_hand_link"/>
  </joint>
</robot>

