<?xml version="1.0"?>

<robot name="inmoov" xmlns:xacro="http://ros.org/wiki/xacro">

  <xacro:include filename="$(find inmoov_description)/urdf/config.joints.urdf.xacro" />
  <xacro:include filename="$(find inmoov_description)/urdf/config.inertial.urdf.xacro" />
  <xacro:include filename="$(find inmoov_description)/urdf/materials.urdf.xacro" />
  <xacro:include filename="$(find inmoov_description)/urdf/asmBase.urdf.xacro" />
  <xacro:include filename="$(find inmoov_description)/urdf/asmTorso.urdf.xacro" />
  <xacro:include filename="$(find inmoov_description)/urdf/asmHead.urdf.xacro" />
  <xacro:include filename="$(find inmoov_description)/urdf/asmEye.urdf.xacro" />
  <xacro:include filename="$(find inmoov_description)/urdf/asmFace.urdf.xacro" />
  <xacro:include filename="$(find inmoov_description)/urdf/asmArm.urdf.xacro" />

  <link name="world"/>

  <joint name="fixed" type="fixed">
    <parent link="world"/>
    <child link="r_shoulder_base_link"/>
  </joint>

  <xacro:arm side="r" flip="1" covers="yes" />

  <link name="r_hand_link">
    <visual>
      <geometry>
        <cylinder length="0.11" radius="0.06"/>
      </geometry> 
      <origin rpy="0 0 0" xyz="0 0 0.055"/>
      <xacro:base_color/>
    </visual>
  </link>

  <joint name="r_wrist_roll_joint" type="revolute">
   <axis xyz="0 0 1"/>
   <limit effort="1000.0" lower="${r_wrist_roll_joint_lower}" upper="${r_wrist_roll_joint_upper}" velocity="${r_wrist_roll_joint_velocity}" />
   <origin rpy="0 0 0" xyz="-0.0144 0.01  -0.2885"/>
   <parent link="r_forearm_link"/>
   <child link="r_hand_link"/>
  </joint>

</robot>